Workbook

Sheet Tabela de Jogos
A1: Tabela de Jogos
A2: Jogo | B2: Seleção A | C2: Gols A | D2: x | E2: Gols B | F2: Seleção B | G2: Vencedor
A3: 1 | B3: México | C3: 2 | D3: x | E3: 0 | F3: África do Sul | G3: =IF(C3>E3,B3,IF(E3>C3,F3,IF(ISBLANK(C3),"-","Empate"))) -> México
A4: 2 | B4: Coreia do Sul | C4: 2 | D4: x | E4: 1 | F4: Tchéquia | G4: =IF(C4>E4,B4,IF(E4>C4,F4,IF(ISBLANK(C4),"-","Empate"))) -> Coreia do Sul
A5: 3 | B5: Canadá | C5: 1 | D5: x | E5: 1 | F5: Bósnia | G5: =IF(C5>E5,B5,IF(E5>C5,F5,IF(ISBLANK(C5),"-","Empate"))) -> Empate
A6: 4 | B6: EUA | C6: 4 | D6: x | E6: 1 | F6: Paraguai | G6: =IF(C6>E6,B6,IF(E6>C6,F6,IF(ISBLANK(C6),"-","Empate"))) -> EUA
A7: 5 | B7: Catar | C7: 1 | D7: x | E7: 1 | F7: Suíça | G7: =IF(C7>E7,B7,IF(E7>C7,F7,IF(ISBLANK(C7),"-","Empate"))) -> Empate
A8: 6 | B8: Brasil | C8: 1 | D8: x | E8: 1 | F8: Marrocos | G8: =IF(C8>E8,B8,IF(E8>C8,F8,IF(ISBLANK(C8),"-","Empate"))) -> Empate
A9: 7 | B9: Haiti | C9: 0 | D9: x | E9: 1 | F9: Escócia | G9: =IF(C9>E9,B9,IF(E9>C9,F9,IF(ISBLANK(C9),"-","Empate"))) -> Escócia
A10: 8 | B10: Austrália | C10: 2 | D10: x | E10: 0 | F10: Turquia | G10: =IF(C10>E10,B10,IF(E10>C10,F10,IF(ISBLANK(C10),"-","Empate"))) -> Austrália
A11: 9 | B11: Alemanha | C11: 7 | D11: x | E11: 1 | F11: Curaçao | G11: =IF(C11>E11,B11,IF(E11>C11,F11,IF(ISBLANK(C11),"-","Empate"))) -> Alemanha
A12: 10 | B12: Holanda | C12: 2 | D12: x | E12: 2 | F12: Japão | G12: =IF(C12>E12,B12,IF(E12>C12,F12,IF(ISBLANK(C12),"-","Empate"))) -> Empate
A13: 11 | B13: Costa do Marfim | C13: 1 | D13: x | E13: 0 | F13: Equador | G13: =IF(C13>E13,B13,IF(E13>C13,F13,IF(ISBLANK(C13),"-","Empate"))) -> Costa do Marfim
A14: 12 | B14: Suécia | C14: 5 | D14: x | E14: 1 | F14: Tunísia | G14: =IF(C14>E14,B14,IF(E14>C14,F14,IF(ISBLANK(C14),"-","Empate"))) -> Suécia
... A60: 58 | B60: Japão | C60: 1 | D60: x | E60: 1 | F60: Suécia | G60: =IF(C60>E60,B60,IF(E60>C60,F60,IF(ISBLANK(C60),"-","Empate"))) -> Empate
A61: 59 | B61: Turquia | D61: x | F61: EUA | G61: =IF(C61>E61,B61,IF(E61>C61,F61,IF(ISBLANK(C61),"-","Empate"))) -> -
A62: 60 | B62: Paraguai | D62: x | F62: Austrália | G62: =IF(C62>E62,B62,IF(E62>C62,F62,IF(ISBLANK(C62),"-","Empate"))) -> -
A63: 61 | B63: Noruega | D63: x | F63: França | G63: =IF(C63>E63,B63,IF(E63>C63,F63,IF(ISBLANK(C63),"-","Empate"))) -> -
A64: 62 | B64: Senegal | D64: x | F64: Iraque | G64: =IF(C64>E64,B64,IF(E64>C64,F64,IF(ISBLANK(C64),"-","Empate"))) -> -
A65: 63 | B65: Cabo Verde | D65: x | F65: Arábia Saudita | G65: =IF(C65>E65,B65,IF(E65>C65,F65,IF(ISBLANK(C65),"-","Empate"))) -> -
A66: 64 | B66: Uruguai | D66: x | F66: Espanha | G66: =IF(C66>E66,B66,IF(E66>C66,F66,IF(ISBLANK(C66),"-","Empate"))) -> -
A67: 65 | B67: Nova Zelândia | D67: x | F67: Bélgica | G67: =IF(C67>E67,B67,IF(E67>C67,F67,IF(ISBLANK(C67),"-","Empate"))) -> -
A68: 66 | B68: Egito | D68: x | F68: Irã | G68: =IF(C68>E68,B68,IF(E68>C68,F68,IF(ISBLANK(C68),"-","Empate"))) -> -
A69: 67 | B69: Panamá | D69: x | F69: Inglaterra | G69: =IF(C69>E69,B69,IF(E69>C69,F69,IF(ISBLANK(C69),"-","Empate"))) -> -
A70: 68 | B70: Croácia | D70: x | F70: Gana | G70: =IF(C70>E70,B70,IF(E70>C70,F70,IF(ISBLANK(C70),"-","Empate"))) -> -
A71: 69 | B71: Colômbia | D71: x | F71: Portugal | G71: =IF(C71>E71,B71,IF(E71>C71,F71,IF(ISBLANK(C71),"-","Empate"))) -> -
A72: 70 | B72: RD Congo | D72: x | F72: Uzbequistão | G72: =IF(C72>E72,B72,IF(E72>C72,F72,IF(ISBLANK(C72),"-","Empate"))) -> -
... A74: 72 | B74: Jordânia | D74: x | F74: Argentina | G74: =IF(C74>E74,B74,IF(E74>C74,F74,IF(ISBLANK(C74),"-","Empate"))) -> -
A75: 73 | D75: x | G75: =IF(C75>E75,B75,IF(E75>C75,F75,IF(ISBLANK(C75),"-","Empate"))) -> -
A76: 74 | D76: x | G76: =IF(C76>E76,B76,IF(E76>C76,F76,IF(ISBLANK(C76),"-","Empate"))) -> -
A77: 75 | D77: x | G77: =IF(C77>E77,B77,IF(E77>C77,F77,IF(ISBLANK(C77),"-","Empate"))) -> -
A78: 76 | D78: x | G78: =IF(C78>E78,B78,IF(E78>C78,F78,IF(ISBLANK(C78),"-","Empate"))) -> -
A79: 77 | D79: x | G79: =IF(C79>E79,B79,IF(E79>C79,F79,IF(ISBLANK(C79),"-","Empate"))) -> -
A80: 78 | D80: x | G80: =IF(C80>E80,B80,IF(E80>C80,F80,IF(ISBLANK(C80),"-","Empate"))) -> -
A81: 79 | D81: x | G81: =IF(C81>E81,B81,IF(E81>C81,F81,IF(ISBLANK(C81),"-","Empate"))) -> -
A82: 80 | D82: x | G82: =IF(C82>E82,B82,IF(E82>C82,F82,IF(ISBLANK(C82),"-","Empate"))) -> -
A83: 81 | D83: x | G83: =IF(C83>E83,B83,IF(E83>C83,F83,IF(ISBLANK(C83),"-","Empate"))) -> -
A84: 82 | D84: x | G84: =IF(C84>E84,B84,IF(E84>C84,F84,IF(ISBLANK(C84),"-","Empate"))) -> -
A85: 83 | D85: x | G85: =IF(C85>E85,B85,IF(E85>C85,F85,IF(ISBLANK(C85),"-","Empate"))) -> -
A86: 84 | D86: x | G86: =IF(C86>E86,B86,IF(E86>C86,F86,IF(ISBLANK(C86),"-","Empate"))) -> -
...

Sheet Classificação
E1: Classificação Geral
B2: Pontos | C2: Acertos | E2: Posição | F2: Nome | G2: Pontos | H2: Acertos
A3: Rodrigo | B3: =Rodrigo!X3 -> 96 | C3: =Rodrigo!Y3 -> 4 | E3: 1 | F3: {=_xlfn.SORTBY(A3:C9,B3:B9,-1,C3:C9,-1,A3:A9,1)} -> Ana | G3: 123 | H3: 5
A4: Arthur | B4: =Arthur!X3 -> 107 | C4: =Arthur!Y3 -> 4 | E4: =IF(AND(G4=G3,H4=H3),E3,2) -> 2 | F4: Arthur | G4: 107 | H4: 4
A5: Dudu | B5: =Dudu!X3 -> 96 | C5: =Dudu!Y3 -> 6 | E5: =IF(AND(G5=G4,H5=H4),E4,3) -> 3 | F5: Isa | G5: 105 | H5: 3
A6: Carol | B6: =Carol!X3 -> 92 | C6: =Carol!Y3 -> 3 | E6: =IF(AND(G6=G5,H6=H5),E5,4) -> 4 | F6: Dudu | G6: 96 | H6: 6
A7: Ana | B7: =Ana!X3 -> 123 | C7: =Ana!Y3 -> 5 | E7: =IF(AND(G7=G6,H7=H6),E6,5) -> 5 | F7: Rodrigo | G7: 96 | H7: 4
A8: Isa | B8: =Isa!X3 -> 105 | C8: =Isa!Y3 -> 3 | E8: =IF(AND(G8=G7,H8=H7),E7,6) -> 6 | F8: Carol | G8: 92 | H8: 3
A9: Trops | B9: =Trops!X3 -> 83 | C9: =Trops!Y3 -> 1 | E9: =IF(AND(G9=G8,H9=H8),E8,7) -> 7 | F9: Trops | G9: 83 | H9: 1

Sheet Rodrigo
A1: ='Tabela de Jogos'!A1 -> Tabela de Jogos | I1: Palpites
A2: ='Tabela de Jogos'!A2 -> Jogo | B2: ='Tabela de Jogos'!B2 -> Seleção A | C2: ='Tabela de Jogos'!C2 -> Gols A | D2: ='Tabela de Jogos'!D2 -> x | E2: ='Tabela de Jogos'!E2 -> Gols B | F2: ='Tabela de Jogos'!F2 -> Seleção B | G2: ='Tabela de Jogos'!G2 -> Vencedor | I2: =A2 -> Jogo | J2: =B2 -> Seleção A | K2: =C2 -> Gols A | L2: =D2 -> x | M2: =E2 -> Gols B | N2: =F2 -> Seleção B | O2: Vencedor | Q2: 6 pontos | R2: 4 pontos | S2: 3 pontos | T2: 2 pontos | U2: 0 pontos | W2: Pontos | X2: Total | Y2: Total de Acertos
A3: ='Tabela de Jogos'!A3 -> 1 | B3: ='Tabela de Jogos'!B3 -> México | C3: ='Tabela de Jogos'!C3 -> 2 | D3: ='Tabela de Jogos'!D3 -> x | E3: ='Tabela de Jogos'!E3 -> 0 | F3: ='Tabela de Jogos'!F3 -> África do Sul | G3: ='Tabela de Jogos'!G3 -> México | I3: =A3 -> 1 | J3: =B3 -> México | K3: 2 | L3: =D3 -> x | M3: 1 | N3: =F3 -> África do Sul | O3: =IF(K3>M3,J3,IF(M3>K3,N3,IF(ISBLANK(K3),"-","Empate"))) -> México | Q3: =IF(AND(O3=G3,K3=C3,M3=E3,ISBLANK(K3)<>TRUE),TRUE,FALSE) -> FALSE | R3: =IF(OR(AND(O3=G3,K3=C3,K3>M3,M3<>E3,ISBLANK(K3)<>TRUE),AND(O3=G3,M3>K3,K3<>C3,M3=E3,ISBLANK(K3)<>TRUE)),TRUE,FALSE) -> TRUE | S3: =IF(AND(O3=G3,ABS(K3-M3)=ABS(C3-E3),OR(K3<>C3,M3<>E3),ISBLANK(K3)<>TRUE),TRUE,FALSE) -> FALSE | T3: =IF(OR(AND(O3=G3,Q3=FALSE,R3=FALSE,S3=FALSE,G3<>"-"),AND(O3="Empate",S3=TRUE)),TRUE,FALSE) -> FALSE | U3: =IF(AND(Q3=FALSE,R3=FALSE,S3=FALSE,T3=FALSE),TRUE,FALSE) -> FALSE | W3: {=IF(OR(J3="Brasil",N3="Brasil"),2*_xlfn.IFS(Q3=TRUE,6,R3=TRUE,4,AND(S3=TRUE,T3=FALSE),3,T3=TRUE,2,U3=TRUE,0),_xlfn.IFS(Q3=TRUE,6,R3=TRUE,4,AND(S3=TRUE,T3=FALSE),3,T3=TRUE,2,U3=TRUE,0))} -> 4 | X3: =SUM(W3:W106) -> 96 | Y3: =COUNTIF(W3:W106,6)+COUNTIF(W3:W106,12) -> 4
A4: ='Tabela de Jogos'!A4 -> 2 | B4: ='Tabela de Jogos'!B4 -> Coreia do Sul | C4: ='Tabela de Jogos'!C4 -> 2 | D4: ='Tabela de Jogos'!D4 -> x | E4: ='Tabela de Jogos'!E4 -> 1 | F4: ='Tabela de Jogos'!F4 -> Tchéquia | G4: ='Tabela de Jogos'!G4 -> Coreia do Sul | I4: =A4 -> 2 | J4: =B4 -> Coreia do Sul | K4: 1 | L4: =D4 -> x | M4: 2 | N4: =F4 -> Tchéquia | O4: =IF(K4>M4,J4,IF(M4>K4,N4,IF(ISBLANK(K4),"-","Empate"))) -> Tchéquia | Q4: =IF(AND(O4=G4,K4=C4,M4=E4,ISBLANK(K4)<>TRUE),TRUE,FALSE) -> FALSE | R4: =IF(OR(AND(O4=G4,K4=C4,K4>M4,M4<>E4,ISBLANK(K4)<>TRUE),AND(O4=G4,M4>K4,K4<>C4,M4=E4,ISBLANK(K4)<>TRUE)),TRUE,FALSE) -> FALSE | S4: =IF(AND(O4=G4,ABS(K4-M4)=ABS(C4-E4),OR(K4<>C4,M4<>E4),ISBLANK(K4)<>TRUE),TRUE,FALSE) -> FALSE | T4: =IF(OR(AND(O4=G4,Q4=FALSE,R4=FALSE,S4=FALSE,G4<>"-"),AND(O4="Empate",S4=TRUE)),TRUE,FALSE) -> FALSE | U4: =IF(AND(Q4=FALSE,R4=FALSE,S4=FALSE,T4=FALSE),TRUE,FALSE) -> TRUE | W4: {=IF(OR(J4="Brasil",N4="Brasil"),2*_xlfn.IFS(Q4=TRUE,6,R4=TRUE,4,AND(S4=TRUE,T4=FALSE),3,T4=TRUE,2,U4=TRUE,0),_xlfn.IFS(Q4=TRUE,6,R4=TRUE,4,AND(S4=TRUE,T4=FALSE),3,T4=TRUE,2,U4=TRUE,0))} -> 0
A5: ='Tabela de Jogos'!A5 -> 3 | B5: ='Tabela de Jogos'!B5 -> Canadá | C5: ='Tabela de Jogos'!C5 -> 1 | D5: ='Tabela de Jogos'!D5 -> x | E5: ='Tabela de Jogos'!E5 -> 1 | F5: ='Tabela de Jogos'!F5 -> Bósnia | G5: ='Tabela de Jogos'!G5 -> Empate | I5: =A5 -> 3 | J5: =B5 -> Canadá | K5: 2 | L5: =D5 -> x | M5: 0 | N5: =F5 -> Bósnia | O5: =IF(K5>M5,J5,IF(M5>K5,N5,IF(ISBLANK(K5),"-","Empate"))) -> Canadá | Q5: =IF(AND(O5=G5,K5=C5,M5=E5,ISBLANK(K5)<>TRUE),TRUE,FALSE) -> FALSE | R5: =IF(OR(AND(O5=G5,K5=C5,K5>M5,M5<>E5,ISBLANK(K5)<>TRUE),AND(O5=G5,M5>K5,K5<>C5,M5=E5,ISBLANK(K5)<>TRUE)),TRUE,FALSE) -> FALSE | S5: =IF(AND(O5=G5,ABS(K5-M5)=ABS(C5-E5),OR(K5<>C5,M5<>E5),ISBLANK(K5)<>TRUE),TRUE,FALSE) -> FALSE | T5: =IF(OR(AND(O5=G5,Q5=FALSE,R5=FALSE,S5=FALSE,G5<>"-"),AND(O5="Empate",S5=TRUE)),TRUE,FALSE) -> FALSE | U5: =IF(AND(Q5=FALSE,R5=FALSE,S5=FALSE,T5=FALSE),TRUE,FALSE) -> TRUE | W5: {=IF(OR(J5="Brasil",N5="Brasil"),2*_xlfn.IFS(Q5=TRUE,6,R5=TRUE,4,AND(S5=TRUE,T5=FALSE),3,T5=TRUE,2,U5=TRUE,0),_xlfn.IFS(Q5=TRUE,6,R5=TRUE,4,AND(S5=TRUE,T5=FALSE),3,T5=TRUE,2,U5=TRUE,0))} -> 0
A6: ='Tabela de Jogos'!A6 -> 4 | B6: ='Tabela de Jogos'!B6 -> EUA | C6: ='Tabela de Jogos'!C6 -> 4 | D6: ='Tabela de Jogos'!D6 -> x | E6: ='Tabela de Jogos'!E6 -> 1 | F6: ='Tabela de Jogos'!F6 -> Paraguai | G6: ='Tabela de Jogos'!G6 -> EUA | I6: =A6 -> 4 | J6: =B6 -> EUA | K6: 1 | L6: =D6 -> x | M6: 0 | N6: =F6 -> Paraguai | O6: =IF(K6>M6,J6,IF(M6>K6,N6,IF(ISBLANK(K6),"-","Empate"))) -> EUA | Q6: =IF(AND(O6=G6,K6=C6,M6=E6,ISBLANK(K6)<>TRUE),TRUE,FALSE) -> FALSE | R6: =IF(OR(AND(O6=G6,K6=C6,K6>M6,M6<>E6,ISBLANK(K6)<>TRUE),AND(O6=G6,M6>K6,K6<>C6,M6=E6,ISBLANK(K6)<>TRUE)),TRUE,FALSE) -> FALSE | S6: =IF(AND(O6=G6,ABS(K6-M6)=ABS(C6-E6),OR(K6<>C6,M6<>E6),ISBLANK(K6)<>TRUE),TRUE,FALSE) -> FALSE | T6: =IF(OR(AND(O6=G6,Q6=FALSE,R6=FALSE,S6=FALSE,G6<>"-"),AND(O6="Empate",S6=TRUE)),TRUE,FALSE) -> TRUE | U6: =IF(AND(Q6=FALSE,R6=FALSE,S6=FALSE,T6=FALSE),TRUE,FALSE) -> FALSE | W6: {=IF(OR(J6="Brasil",N6="Brasil"),2*_xlfn.IFS(Q6=TRUE,6,R6=TRUE,4,AND(S6=TRUE,T6=FALSE),3,T6=TRUE,2,U6=TRUE,0),_xlfn.IFS(Q6=TRUE,6,R6=TRUE,4,AND(S6=TRUE,T6=FALSE),3,T6=TRUE,2,U6=TRUE,0))} -> 2
A7: ='Tabela de Jogos'!A7 -> 5 | B7: ='Tabela de Jogos'!B7 -> Catar | C7: ='Tabela de Jogos'!C7 -> 1 | D7: ='Tabela de Jogos'!D7 -> x | E7: ='Tabela de Jogos'!E7 -> 1 | F7: ='Tabela de Jogos'!F7 -> Suíça | G7: ='Tabela de Jogos'!G7 -> Empate | I7: =A7 -> 5 | J7: =B7 -> Catar | K7: 0 | L7: =D7 -> x | M7: 3 | N7: =F7 -> Suíça | O7: =IF(K7>M7,J7,IF(M7>K7,N7,IF(ISBLANK(K7),"-","Empate"))) -> Suíça | Q7: =IF(AND(O7=G7,K7=C7,M7=E7,ISBLANK(K7)<>TRUE),TRUE,FALSE) -> FALSE | R7: =IF(OR(AND(O7=G7,K7=C7,K7>M7,M7<>E7,ISBLANK(K7)<>TRUE),AND(O7=G7,M7>K7,K7<>C7,M7=E7,ISBLANK(K7)<>TRUE)),TRUE,FALSE) -> FALSE | S7: =IF(AND(O7=G7,ABS(K7-M7)=ABS(C7-E7),OR(K7<>C7,M7<>E7),ISBLANK(K7)<>TRUE),TRUE,FALSE) -> FALSE | T7: =IF(OR(AND(O7=G7,Q7=FALSE,R7=FALSE,S7=FALSE,G7<>"-"),AND(O7="Empate",S7=TRUE)),TRUE,FALSE) -> FALSE | U7: =IF(AND(Q7=FALSE,R7=FALSE,S7=FALSE,T7=FALSE),TRUE,FALSE) -> TRUE | W7: {=IF(OR(J7="Brasil",N7="Brasil"),2*_xlfn.IFS(Q7=TRUE,6,R7=TRUE,4,AND(S7=TRUE,T7=FALSE),3,T7=TRUE,2,U7=TRUE,0),_xlfn.IFS(Q7=TRUE,6,R7=TRUE,4,AND(S7=TRUE,T7=FALSE),3,T7=TRUE,2,U7=TRUE,0))} -> 0
A8: ='Tabela de Jogos'!A8 -> 6 | B8: ='Tabela de Jogos'!B8 -> Brasil | C8: ='Tabela de Jogos'!C8 -> 1 | D8: ='Tabela de Jogos'!D8 -> x | E8: ='Tabela de Jogos'!E8 -> 1 | F8: ='Tabela de Jogos'!F8 -> Marrocos | G8: ='Tabela de Jogos'!G8 -> Empate | I8: =A8 -> 6 | J8: =B8 -> Brasil | K8: 2 | L8: =D8 -> x | M8: 1 | N8: =F8 -> Marrocos | O8: =IF(K8>M8,J8,IF(M8>K8,N8,IF(ISBLANK(K8),"-","Empate"))) -> Brasil | Q8: =IF(AND(O8=G8,K8=C8,M8=E8,ISBLANK(K8)<>TRUE),TRUE,FALSE) -> FALSE | R8: =IF(OR(AND(O8=G8,K8=C8,K8>M8,M8<>E8,ISBLANK(K8)<>TRUE),AND(O8=G8,M8>K8,K8<>C8,M8=E8,ISBLANK(K8)<>TRUE)),TRUE,FALSE) -> FALSE | S8: =IF(AND(O8=G8,ABS(K8-M8)=ABS(C8-E8),OR(K8<>C8,M8<>E8),ISBLANK(K8)<>TRUE),TRUE,FALSE) -> FALSE | T8: =IF(OR(AND(O8=G8,Q8=FALSE,R8=FALSE,S8=FALSE,G8<>"-"),AND(O8="Empate",S8=TRUE)),TRUE,FALSE) -> FALSE | U8: =IF(AND(Q8=FALSE,R8=FALSE,S8=FALSE,T8=FALSE),TRUE,FALSE) -> TRUE | W8: {=IF(OR(J8="Brasil",N8="Brasil"),2*_xlfn.IFS(Q8=TRUE,6,R8=TRUE,4,AND(S8=TRUE,T8=FALSE),3,T8=TRUE,2,U8=TRUE,0),_xlfn.IFS(Q8=TRUE,6,R8=TRUE,4,AND(S8=TRUE,T8=FALSE),3,T8=TRUE,2,U8=TRUE,0))} -> 0
A9: ='Tabela de Jogos'!A9 -> 7 | B9: ='Tabela de Jogos'!B9 -> Haiti | C9: ='Tabela de Jogos'!C9 -> 0 | D9: ='Tabela de Jogos'!D9 -> x | E9: ='Tabela de Jogos'!E9 -> 1 | F9: ='Tabela de Jogos'!F9 -> Escócia | G9: ='Tabela de Jogos'!G9 -> Escócia | I9: =A9 -> 7 | J9: =B9 -> Haiti | K9: 0 | L9: =D9 -> x | M9: 2 | N9: =F9 -> Escócia | O9: =IF(K9>M9,J9,IF(M9>K9,N9,IF(ISBLANK(K9),"-","Empate"))) -> Escócia | Q9: =IF(AND(O9=G9,K9=C9,M9=E9,ISBLANK(K9)<>TRUE),TRUE,FALSE) -> FALSE | R9: =IF(OR(AND(O9=G9,K9=C9,K9>M9,M9<>E9,ISBLANK(K9)<>TRUE),AND(O9=G9,M9>K9,K9<>C9,M9=E9,ISBLANK(K9)<>TRUE)),TRUE,FALSE) -> FALSE | S9: =IF(AND(O9=G9,ABS(K9-M9)=ABS(C9-E9),OR(K9<>C9,M9<>E9),ISBLANK(K9)<>TRUE),TRUE,FALSE) -> FALSE | T9: =IF(OR(AND(O9=G9,Q9=FALSE,R9=FALSE,S9=FALSE,G9<>"-"),AND(O9="Empate",S9=TRUE)),TRUE,FALSE) -> TRUE | U9: =IF(AND(Q9=FALSE,R9=FALSE,S9=FALSE,T9=FALSE),TRUE,FALSE) -> FALSE | W9: {=IF(OR(J9="Brasil",N9="Brasil"),2*_xlfn.IFS(Q9=TRUE,6,R9=TRUE,4,AND(S9=TRUE,T9=FALSE),3,T9=TRUE,2,U9=TRUE,0),_xlfn.IFS(Q9=TRUE,6,R9=TRUE,4,AND(S9=TRUE,T9=FALSE),3,T9=TRUE,2,U9=TRUE,0))} -> 2
A10: ='Tabela de Jogos'!A10 -> 8 | B10: ='Tabela de Jogos'!B10 -> Austrália | C10: ='Tabela de Jogos'!C10 -> 2 | D10: ='Tabela de Jogos'!D10 -> x | E10: ='Tabela de Jogos'!E10 -> 0 | F10: ='Tabela de Jogos'!F10 -> Turquia | G10: ='Tabela de Jogos'!G10 -> Austrália | I10: =A10 -> 8 | J10: =B10 -> Austrália | K10: 1 | L10: =D10 -> x | M10: 1 | N10: =F10 -> Turquia | O10: =IF(K10>M10,J10,IF(M10>K10,N10,IF(ISBLANK(K10),"-","Empate"))) -> Empate | Q10: =IF(AND(O10=G10,K10=C10,M10=E10,ISBLANK(K10)<>TRUE),TRUE,FALSE) -> FALSE | R10: =IF(OR(AND(O10=G10,K10=C10,K10>M10,M10<>E10,ISBLANK(K10)<>TRUE),AND(O10=G10,M10>K10,K10<>C10,M10=E10,ISBLANK(K10)<>TRUE)),TRUE,FALSE) -> FALSE | S10: =IF(AND(O10=G10,ABS(K10-M10)=ABS(C10-E10),OR(K10<>C10,M10<>E10),ISBLANK(K10)<>TRUE),TRUE,FALSE) -> FALSE | T10: =IF(OR(AND(O10=G10,Q10=FALSE,R10=FALSE,S10=FALSE,G10<>"-"),AND(O10="Empate",S10=TRUE)),TRUE,FALSE) -> FALSE | U10: =IF(AND(Q10=FALSE,R10=FALSE,S10=FALSE,T10=FALSE),TRUE,FALSE) -> TRUE | W10: {=IF(OR(J10="Brasil",N10="Brasil"),2*_xlfn.IFS(Q10=TRUE,6,R10=TRUE,4,AND(S10=TRUE,T10=FALSE),3,T10=TRUE,2,U10=TRUE,0),_xlfn.IFS(Q10=TRUE,6,R10=TRUE,4,AND(S10=TRUE,T10=FALSE),3,T10=TRUE,2,U10=TRUE,0))} -> 0
A11: ='Tabela de Jogos'!A11 -> 9 | B11: ='Tabela de Jogos'!B11 -> Alemanha | C11: ='Tabela de Jogos'!C11 -> 7 | D11: ='Tabela de Jogos'!D11 -> x | E11: ='Tabela de Jogos'!E11 -> 1 | F11: ='Tabela de Jogos'!F11 -> Curaçao | G11: ='Tabela de Jogos'!G11 -> Alemanha | I11: =A11 -> 9 | J11: =B11 -> Alemanha | K11: 5 | L11: =D11 -> x | M11: 0 | N11: =F11 -> Curaçao | O11: =IF(K11>M11,J11,IF(M11>K11,N11,IF(ISBLANK(K11),"-","Empate"))) -> Alemanha | Q11: =IF(AND(O11=G11,K11=C11,M11=E11,ISBLANK(K11)<>TRUE),TRUE,FALSE) -> FALSE | R11: =IF(OR(AND(O11=G11,K11=C11,K11>M11,M11<>E11,ISBLANK(K11)<>TRUE),AND(O11=G11,M11>K11,K11<>C11,M11=E11,ISBLANK(K11)<>TRUE)),TRUE,FALSE) -> FALSE | S11: =IF(AND(O11=G11,ABS(K11-M11)=ABS(C11-E11),OR(K11<>C11,M11<>E11),ISBLANK(K11)<>TRUE),TRUE,FALSE) -> FALSE | T11: =IF(OR(AND(O11=G11,Q11=FALSE,R11=FALSE,S11=FALSE,G11<>"-"),AND(O11="Empate",S11=TRUE)),TRUE,FALSE) -> TRUE | U11: =IF(AND(Q11=FALSE,R11=FALSE,S11=FALSE,T11=FALSE),TRUE,FALSE) -> FALSE | W11: {=IF(OR(J11="Brasil",N11="Brasil"),2*_xlfn.IFS(Q11=TRUE,6,R11=TRUE,4,AND(S11=TRUE,T11=FALSE),3,T11=TRUE,2,U11=TRUE,0),_xlfn.IFS(Q11=TRUE,6,R11=TRUE,4,AND(S11=TRUE,T11=FALSE),3,T11=TRUE,2,U11=TRUE,0))} -> 2
A12: ='Tabela de Jogos'!A12 -> 10 | B12: ='Tabela de Jogos'!B12 -> Holanda | C12: ='Tabela de Jogos'!C12 -> 2 | D12: ='Tabela de Jogos'!D12 -> x | E12: ='Tabela de Jogos'!E12 -> 2 | F12: ='Tabela de Jogos'!F12 -> Japão | G12: ='Tabela de Jogos'!G12 -> Empate | I12: =A12 -> 10 | J12: =B12 -> Holanda | K12: 1 | L12: =D12 -> x | M12: 2 | N12: =F12 -> Japão | O12: =IF(K12>M12,J12,IF(M12>K12,N12,IF(ISBLANK(K12),"-","Empate"))) -> Japão | Q12: =IF(AND(O12=G12,K12=C12,M12=E12,ISBLANK(K12)<>TRUE),TRUE,FALSE) -> FALSE | R12: =IF(OR(AND(O12=G12,K12=C12,K12>M12,M12<>E12,ISBLANK(K12)<>TRUE),AND(O12=G12,M12>K12,K12<>C12,M12=E12,ISBLANK(K12)<>TRUE)),TRUE,FALSE) -> FALSE | S12: =IF(AND(O12=G12,ABS(K12-M12)=ABS(C12-E12),OR(K12<>C12,M12<>E12),ISBLANK(K12)<>TRUE),TRUE,FALSE) -> FALSE | T12: =IF(OR(AND(O12=G12,Q12=FALSE,R12=FALSE,S12=FALSE,G12<>"-"),AND(O12="Empate",S12=TRUE)),TRUE,FALSE) -> FALSE | U12: =IF(AND(Q12=FALSE,R12=FALSE,S12=FALSE,T12=FALSE),TRUE,FALSE) -> TRUE | W12: {=IF(OR(J12="Brasil",N12="Brasil"),2*_xlfn.IFS(Q12=TRUE,6,R12=TRUE,4,AND(S12=TRUE,T12=FALSE),3,T12=TRUE,2,U12=TRUE,0),_xlfn.IFS(Q12=TRUE,6,R12=TRUE,4,AND(S12=TRUE,T12=FALSE),3,T12=TRUE,2,U12=TRUE,0))} -> 0
A13: ='Tabela de Jogos'!A13 -> 11 | B13: ='Tabela de Jogos'!B13 -> Costa do Marfim | C13: ='Tabela de Jogos'!C13 -> 1 | D13: ='Tabela de Jogos'!D13 -> x | E13: ='Tabela de Jogos'!E13 -> 0 | F13: ='Tabela de Jogos'!F13 -> Equador | G13: ='Tabela de Jogos'!G13 -> Costa do Marfim | I13: =A13 -> 11 | J13: =B13 -> Costa do Marfim | K13: 1 | L13: =D13 -> x | M13: 1 | N13: =F13 -> Equador | O13: =IF(K13>M13,J13,IF(M13>K13,N13,IF(ISBLANK(K13),"-","Empate"))) -> Empate | Q13: =IF(AND(O13=G13,K13=C13,M13=E13,ISBLANK(K13)<>TRUE),TRUE,FALSE) -> FALSE | R13: =IF(OR(AND(O13=G13,K13=C13,K13>M13,M13<>E13,ISBLANK(K13)<>TRUE),AND(O13=G13,M13>K13,K13<>C13,M13=E13,ISBLANK(K13)<>TRUE)),TRUE,FALSE) -> FALSE | S13: =IF(AND(O13=G13,ABS(K13-M13)=ABS(C13-E13),OR(K13<>C13,M13<>E13),ISBLANK(K13)<>TRUE),TRUE,FALSE) -> FALSE | T13: =IF(OR(AND(O13=G13,Q13=FALSE,R13=FALSE,S13=FALSE,G13<>"-"),AND(O13="Empate",S13=TRUE)),TRUE,FALSE) -> FALSE | U13: =IF(AND(Q13=FALSE,R13=FALSE,S13=FALSE,T13=FALSE),TRUE,FALSE) -> TRUE | W13: {=IF(OR(J13="Brasil",N13="Brasil"),2*_xlfn.IFS(Q13=TRUE,6,R13=TRUE,4,AND(S13=TRUE,T13=FALSE),3,T13=TRUE,2,U13=TRUE,0),_xlfn.IFS(Q13=TRUE,6,R13=TRUE,4,AND(S13=TRUE,T13=FALSE),3,T13=TRUE,2,U13=TRUE,0))} -> 0
A14: ='Tabela de Jogos'!A14 -> 12 | B14: ='Tabela de Jogos'!B14 -> Suécia | C14: ='Tabela de Jogos'!C14 -> 5 | D14: ='Tabela de Jogos'!D14 -> x | E14: ='Tabela de Jogos'!E14 -> 1 | F14: ='Tabela de Jogos'!F14 -> Tunísia | G14: ='Tabela de Jogos'!G14 -> Suécia | I14: =A14 -> 12 | J14: =B14 -> Suécia | K14: 1 | L14: =D14 -> x | M14: 0 | N14: =F14 -> Tunísia | O14: =IF(K14>M14,J14,IF(M14>K14,N14,IF(ISBLANK(K14),"-","Empate"))) -> Suécia | Q14: =IF(AND(O14=G14,K14=C14,M14=E14,ISBLANK(K14)<>TRUE),TRUE,FALSE) -> FALSE | R14: =IF(OR(AND(O14=G14,K14=C14,K14>M14,M14<>E14,ISBLANK(K14)<>TRUE),AND(O14=G14,M14>K14,K14<>C14,M14=E14,ISBLANK(K14)<>TRUE)),TRUE,FALSE) -> FALSE | S14: =IF(AND(O14=G14,ABS(K14-M14)=ABS(C14-E14),OR(K14<>C14,M14<>E14),ISBLANK(K14)<>TRUE),TRUE,FALSE) -> FALSE | T14: =IF(OR(AND(O14=G14,Q14=FALSE,R14=FALSE,S14=FALSE,G14<>"-"),AND(O14="Empate",S14=TRUE)),TRUE,FALSE) -> TRUE | U14: =IF(AND(Q14=FALSE,R14=FALSE,S14=FALSE,T14=FALSE),TRUE,FALSE) -> FALSE | W14: {=IF(OR(J14="Brasil",N14="Brasil"),2*_xlfn.IFS(Q14=TRUE,6,R14=TRUE,4,AND(S14=TRUE,T14=FALSE),3,T14=TRUE,2,U14=TRUE,0),_xlfn.IFS(Q14=TRUE,6,R14=TRUE,4,AND(S14=TRUE,T14=FALSE),3,T14=TRUE,2,U14=TRUE,0))} -> 2
A15: ='Tabela de Jogos'!A15 -> 13 | B15: ='Tabela de Jogos'!B15 -> Espanha | C15: ='Tabela de Jogos'!C15 -> 0 | D15: ='Tabela de Jogos'!D15 -> x | E15: ='Tabela de Jogos'!E15 -> 0 | F15: ='Tabela de Jogos'!F15 -> Cabo Verde | G15: ='Tabela de Jogos'!G15 -> Empate | I15: =A15 -> 13 | J15: =B15 -> Espanha | K15: 6 | L15: =D15 -> x | M15: 0 | N15: =F15 -> Cabo Verde | O15: =IF(K15>M15,J15,IF(M15>K15,N15,IF(ISBLANK(K15),"-","Empate"))) -> Espanha | Q15: =IF(AND(O15=G15,K15=C15,M15=E15,ISBLANK(K15)<>TRUE),TRUE,FALSE) -> FALSE | R15: =IF(OR(AND(O15=G15,K15=C15,K15>M15,M15<>E15,ISBLANK(K15)<>TRUE),AND(O15=G15,M15>K15,K15<>C15,M15=E15,ISBLANK(K15)<>TRUE)),TRUE,FALSE) -> FALSE | S15: =IF(AND(O15=G15,ABS(K15-M15)=ABS(C15-E15),OR(K15<>C15,M15<>E15),ISBLANK(K15)<>TRUE),TRUE,FALSE) -> FALSE | T15: =IF(OR(AND(O15=G15,Q15=FALSE,R15=FALSE,S15=FALSE,G15<>"-"),AND(O15="Empate",S15=TRUE)),TRUE,FALSE) -> FALSE | U15: =IF(AND(Q15=FALSE,R15=FALSE,S15=FALSE,T15=FALSE),TRUE,FALSE) -> TRUE | W15: {=IF(OR(J15="Brasil",N15="Brasil"),2*_xlfn.IFS(Q15=TRUE,6,R15=TRUE,4,AND(S15=TRUE,T15=FALSE),3,T15=TRUE,2,U15=TRUE,0),_xlfn.IFS(Q15=TRUE,6,R15=TRUE,4,AND(S15=TRUE,T15=FALSE),3,T15=TRUE,2,U15=TRUE,0))} -> 0
... A62: ='Tabela de Jogos'!A62 -> 60 | B62: ='Tabela de Jogos'!B62 -> Paraguai | C62: ='Tabela de Jogos'!C62 -> 0 | D62: ='Tabela de Jogos'!D62 -> x | E62: ='Tabela de Jogos'!E62 -> 0 | F62: ='Tabela de Jogos'!F62 -> Austrália | G62: ='Tabela de Jogos'!G62 -> - | I62: =A62 -> 60 | J62: =B62 -> Paraguai | K62: 1 | L62: =D62 -> x | M62: 0 | N62: =F62 -> Austrália | O62: =IF(K62>M62,J62,IF(M62>K62,N62,IF(ISBLANK(K62),"-","Empate"))) -> Paraguai | Q62: =IF(AND(O62=G62,K62=C62,M62=E62,ISBLANK(K62)<>TRUE),TRUE,FALSE) -> FALSE | R62: =IF(OR(AND(O62=G62,K62=C62,K62>M62,M62<>E62,ISBLANK(K62)<>TRUE),AND(O62=G62,M62>K62,K62<>C62,M62=E62,ISBLANK(K62)<>TRUE)),TRUE,FALSE) -> FALSE | S62: =IF(AND(O62=G62,ABS(K62-M62)=ABS(C62-E62),OR(K62<>C62,M62<>E62),ISBLANK(K62)<>TRUE),TRUE,FALSE) -> FALSE | T62: =IF(OR(AND(O62=G62,Q62=FALSE,R62=FALSE,S62=FALSE,G62<>"-"),AND(O62="Empate",S62=TRUE)),TRUE,FALSE) -> FALSE | U62: =IF(AND(Q62=FALSE,R62=FALSE,S62=FALSE,T62=FALSE),TRUE,FALSE) -> TRUE | W62: {=IF(OR(J62="Brasil",N62="Brasil"),2*_xlfn.IFS(Q62=TRUE,6,R62=TRUE,4,AND(S62=TRUE,T62=FALSE),3,T62=TRUE,2,U62=TRUE,0),_xlfn.IFS(Q62=TRUE,6,R62=TRUE,4,AND(S62=TRUE,T62=FALSE),3,T62=TRUE,2,U62=TRUE,0))} -> 0
A63: ='Tabela de Jogos'!A63 -> 61 | B63: ='Tabela de Jogos'!B63 -> Noruega | C63: ='Tabela de Jogos'!C63 -> 0 | D63: ='Tabela de Jogos'!D63 -> x | E63: ='Tabela de Jogos'!E63 -> 0 | F63: ='Tabela de Jogos'!F63 -> França | G63: ='Tabela de Jogos'!G63 -> - | I63: =A63 -> 61 | J63: =B63 -> Noruega | L63: =D63 -> x | N63: =F63 -> França | O63: =IF(K63>M63,J63,IF(M63>K63,N63,IF(ISBLANK(K63),"-","Empate"))) -> - | Q63: =IF(AND(O63=G63,K63=C63,M63=E63,ISBLANK(K63)<>TRUE),TRUE,FALSE) -> FALSE | R63: =IF(OR(AND(O63=G63,K63=C63,K63>M63,M63<>E63,ISBLANK(K63)<>TRUE),AND(O63=G63,M63>K63,K63<>C63,M63=E63,ISBLANK(K63)<>TRUE)),TRUE,FALSE) -> FALSE | S63: =IF(AND(O63=G63,ABS(K63-M63)=ABS(C63-E63),OR(K63<>C63,M63<>E63),ISBLANK(K63)<>TRUE),TRUE,FALSE) -> FALSE | T63: =IF(OR(AND(O63=G63,Q63=FALSE,R63=FALSE,S63=FALSE,G63<>"-"),AND(O63="Empate",S63=TRUE)),TRUE,FALSE) -> FALSE | U63: =IF(AND(Q63=FALSE,R63=FALSE,S63=FALSE,T63=FALSE),TRUE,FALSE) -> TRUE | W63: {=IF(OR(J63="Brasil",N63="Brasil"),2*_xlfn.IFS(Q63=TRUE,6,R63=TRUE,4,AND(S63=TRUE,T63=FALSE),3,T63=TRUE,2,U63=TRUE,0),_xlfn.IFS(Q63=TRUE,6,R63=TRUE,4,AND(S63=TRUE,T63=FALSE),3,T63=TRUE,2,U63=TRUE,0))} -> 0
A64: ='Tabela de Jogos'!A64 -> 62 | B64: ='Tabela de Jogos'!B64 -> Senegal | C64: ='Tabela de Jogos'!C64 -> 0 | D64: ='Tabela de Jogos'!D64 -> x | E64: ='Tabela de Jogos'!E64 -> 0 | F64: ='Tabela de Jogos'!F64 -> Iraque | G64: ='Tabela de Jogos'!G64 -> - | I64: =A64 -> 62 | J64: =B64 -> Senegal | L64: =D64 -> x | N64: =F64 -> Iraque | O64: =IF(K64>M64,J64,IF(M64>K64,N64,IF(ISBLANK(K64),"-","Empate"))) -> - | Q64: =IF(AND(O64=G64,K64=C64,M64=E64,ISBLANK(K64)<>TRUE),TRUE,FALSE) -> FALSE | R64: =IF(OR(AND(O64=G64,K64=C64,K64>M64,M64<>E64,ISBLANK(K64)<>TRUE),AND(O64=G64,M64>K64,K64<>C64,M64=E64,ISBLANK(K64)<>TRUE)),TRUE,FALSE) -> FALSE | S64: =IF(AND(O64=G64,ABS(K64-M64)=ABS(C64-E64),OR(K64<>C64,M64<>E64),ISBLANK(K64)<>TRUE),TRUE,FALSE) -> FALSE | T64: =IF(OR(AND(O64=G64,Q64=FALSE,R64=FALSE,S64=FALSE,G64<>"-"),AND(O64="Empate",S64=TRUE)),TRUE,FALSE) -> FALSE | U64: =IF(AND(Q64=FALSE,R64=FALSE,S64=FALSE,T64=FALSE),TRUE,FALSE) -> TRUE | W64: {=IF(OR(J64="Brasil",N64="Brasil"),2*_xlfn.IFS(Q64=TRUE,6,R64=TRUE,4,AND(S64=TRUE,T64=FALSE),3,T64=TRUE,2,U64=TRUE,0),_xlfn.IFS(Q64=TRUE,6,R64=TRUE,4,AND(S64=TRUE,T64=FALSE),3,T64=TRUE,2,U64=TRUE,0))} -> 0
A65: ='Tabela de Jogos'!A65 -> 63 | B65: ='Tabela de Jogos'!B65 -> Cabo Verde | C65: ='Tabela de Jogos'!C65 -> 0 | D65: ='Tabela de Jogos'!D65 -> x | E65: ='Tabela de Jogos'!E65 -> 0 | F65: ='Tabela de Jogos'!F65 -> Arábia Saudita | G65: ='Tabela de Jogos'!G65 -> - | I65: =A65 -> 63 | J65: =B65 -> Cabo Verde | L65: =D65 -> x | N65: =F65 -> Arábia Saudita | O65: =IF(K65>M65,J65,IF(M65>K65,N65,IF(ISBLANK(K65),"-","Empate"))) -> - | Q65: =IF(AND(O65=G65,K65=C65,M65=E65,ISBLANK(K65)<>TRUE),TRUE,FALSE) -> FALSE | R65: =IF(OR(AND(O65=G65,K65=C65,K65>M65,M65<>E65,ISBLANK(K65)<>TRUE),AND(O65=G65,M65>K65,K65<>C65,M65=E65,ISBLANK(K65)<>TRUE)),TRUE,FALSE) -> FALSE | S65: =IF(AND(O65=G65,ABS(K65-M65)=ABS(C65-E65),OR(K65<>C65,M65<>E65),ISBLANK(K65)<>TRUE),TRUE,FALSE) -> FALSE | T65: =IF(OR(AND(O65=G65,Q65=FALSE,R65=FALSE,S65=FALSE,G65<>"-"),AND(O65="Empate",S65=TRUE)),TRUE,FALSE) -> FALSE | U65: =IF(AND(Q65=FALSE,R65=FALSE,S65=FALSE,T65=FALSE),TRUE,FALSE) -> TRUE | W65: {=IF(OR(J65="Brasil",N65="Brasil"),2*_xlfn.IFS(Q65=TRUE,6,R65=TRUE,4,AND(S65=TRUE,T65=FALSE),3,T65=TRUE,2,U65=TRUE,0),_xlfn.IFS(Q65=TRUE,6,R65=TRUE,4,AND(S65=TRUE,T65=FALSE),3,T65=TRUE,2,U65=TRUE,0))} -> 0
A66: ='Tabela de Jogos'!A66 -> 64 | B66: ='Tabela de Jogos'!B66 -> Uruguai | C66: ='Tabela de Jogos'!C66 -> 0 | D66: ='Tabela de Jogos'!D66 -> x | E66: ='Tabela de Jogos'!E66 -> 0 | F66: ='Tabela de Jogos'!F66 -> Espanha | G66: ='Tabela de Jogos'!G66 -> - | I66: =A66 -> 64 | J66: =B66 -> Uruguai | L66: =D66 -> x | N66: =F66 -> Espanha | O66: =IF(K66>M66,J66,IF(M66>K66,N66,IF(ISBLANK(K66),"-","Empate"))) -> - | Q66: =IF(AND(O66=G66,K66=C66,M66=E66,ISBLANK(K66)<>TRUE),TRUE,FALSE) -> FALSE | R66: =IF(OR(AND(O66=G66,K66=C66,K66>M66,M66<>E66,ISBLANK(K66)<>TRUE),AND(O66=G66,M66>K66,K66<>C66,M66=E66,ISBLANK(K66)<>TRUE)),TRUE,FALSE) -> FALSE | S66: =IF(AND(O66=G66,ABS(K66-M66)=ABS(C66-E66),OR(K66<>C66,M66<>E66),ISBLANK(K66)<>TRUE),TRUE,FALSE) -> FALSE | T66: =IF(OR(AND(O66=G66,Q66=FALSE,R66=FALSE,S66=FALSE,G66<>"-"),AND(O66="Empate",S66=TRUE)),TRUE,FALSE) -> FALSE | U66: =IF(AND(Q66=FALSE,R66=FALSE,S66=FALSE,T66=FALSE),TRUE,FALSE) -> TRUE | W66: {=IF(OR(J66="Brasil",N66="Brasil"),2*_xlfn.IFS(Q66=TRUE,6,R66=TRUE,4,AND(S66=TRUE,T66=FALSE),3,T66=TRUE,2,U66=TRUE,0),_xlfn.IFS(Q66=TRUE,6,R66=TRUE,4,AND(S66=TRUE,T66=FALSE),3,T66=TRUE,2,U66=TRUE,0))} -> 0
A67: ='Tabela de Jogos'!A67 -> 65 | B67: ='Tabela de Jogos'!B67 -> Nova Zelândia | C67: ='Tabela de Jogos'!C67 -> 0 | D67: ='Tabela de Jogos'!D67 -> x | E67: ='Tabela de Jogos'!E67 -> 0 | F67: ='Tabela de Jogos'!F67 -> Bélgica | G67: ='Tabela de Jogos'!G67 -> - | I67: =A67 -> 65 | J67: =B67 -> Nova Zelândia | L67: =D67 -> x | N67: =F67 -> Bélgica | O67: =IF(K67>M67,J67,IF(M67>K67,N67,IF(ISBLANK(K67),"-","Empate"))) -> - | Q67: =IF(AND(O67=G67,K67=C67,M67=E67,ISBLANK(K67)<>TRUE),TRUE,FALSE) -> FALSE | R67: =IF(OR(AND(O67=G67,K67=C67,K67>M67,M67<>E67,ISBLANK(K67)<>TRUE),AND(O67=G67,M67>K67,K67<>C67,M67=E67,ISBLANK(K67)<>TRUE)),TRUE,FALSE) -> FALSE | S67: =IF(AND(O67=G67,ABS(K67-M67)=ABS(C67-E67),OR(K67<>C67,M67<>E67),ISBLANK(K67)<>TRUE),TRUE,FALSE) -> FALSE | T67: =IF(OR(AND(O67=G67,Q67=FALSE,R67=FALSE,S67=FALSE,G67<>"-"),AND(O67="Empate",S67=TRUE)),TRUE,FALSE) -> FALSE | U67: =IF(AND(Q67=FALSE,R67=FALSE,S67=FALSE,T67=FALSE),TRUE,FALSE) -> TRUE | W67: {=IF(OR(J67="Brasil",N67="Brasil"),2*_xlfn.IFS(Q67=TRUE,6,R67=TRUE,4,AND(S67=TRUE,T67=FALSE),3,T67=TRUE,2,U67=TRUE,0),_xlfn.IFS(Q67=TRUE,6,R67=TRUE,4,AND(S67=TRUE,T67=FALSE),3,T67=TRUE,2,U67=TRUE,0))} -> 0
A68: ='Tabela de Jogos'!A68 -> 66 | B68: ='Tabela de Jogos'!B68 -> Egito | C68: ='Tabela de Jogos'!C68 -> 0 | D68: ='Tabela de Jogos'!D68 -> x | E68: ='Tabela de Jogos'!E68 -> 0 | F68: ='Tabela de Jogos'!F68 -> Irã | G68: ='Tabela de Jogos'!G68 -> - | I68: =A68 -> 66 | J68: =B68 -> Egito | L68: =D68 -> x | N68: =F68 -> Irã | O68: =IF(K68>M68,J68,IF(M68>K68,N68,IF(ISBLANK(K68),"-","Empate"))) -> - | Q68: =IF(AND(O68=G68,K68=C68,M68=E68,ISBLANK(K68)<>TRUE),TRUE,FALSE) -> FALSE | R68: =IF(OR(AND(O68=G68,K68=C68,K68>M68,M68<>E68,ISBLANK(K68)<>TRUE),AND(O68=G68,M68>K68,K68<>C68,M68=E68,ISBLANK(K68)<>TRUE)),TRUE,FALSE) -> FALSE | S68: =IF(AND(O68=G68,ABS(K68-M68)=ABS(C68-E68),OR(K68<>C68,M68<>E68),ISBLANK(K68)<>TRUE),TRUE,FALSE) -> FALSE | T68: =IF(OR(AND(O68=G68,Q68=FALSE,R68=FALSE,S68=FALSE,G68<>"-"),AND(O68="Empate",S68=TRUE)),TRUE,FALSE) -> FALSE | U68: =IF(AND(Q68=FALSE,R68=FALSE,S68=FALSE,T68=FALSE),TRUE,FALSE) -> TRUE | W68: {=IF(OR(J68="Brasil",N68="Brasil"),2*_xlfn.IFS(Q68=TRUE,6,R68=TRUE,4,AND(S68=TRUE,T68=FALSE),3,T68=TRUE,2,U68=TRUE,0),_xlfn.IFS(Q68=TRUE,6,R68=TRUE,4,AND(S68=TRUE,T68=FALSE),3,T68=TRUE,2,U68=TRUE,0))} -> 0
A69: ='Tabela de Jogos'!A69 -> 67 | B69: ='Tabela de Jogos'!B69 -> Panamá | C69: ='Tabela de Jogos'!C69 -> 0 | D69: ='Tabela de Jogos'!D69 -> x | E69: ='Tabela de Jogos'!E69 -> 0 | F69: ='Tabela de Jogos'!F69 -> Inglaterra | G69: ='Tabela de Jogos'!G69 -> - | I69: =A69 -> 67 | J69: =B69 -> Panamá | L69: =D69 -> x | N69: =F69 -> Inglaterra | O69: =IF(K69>M69,J69,IF(M69>K69,N69,IF(ISBLANK(K69),"-","Empate"))) -> - | Q69: =IF(AND(O69=G69,K69=C69,M69=E69,ISBLANK(K69)<>TRUE),TRUE,FALSE) -> FALSE | R69: =IF(OR(AND(O69=G69,K69=C69,K69>M69,M69<>E69,ISBLANK(K69)<>TRUE),AND(O69=G69,M69>K69,K69<>C69,M69=E69,ISBLANK(K69)<>TRUE)),TRUE,FALSE) -> FALSE | S69: =IF(AND(O69=G69,ABS(K69-M69)=ABS(C69-E69),OR(K69<>C69,M69<>E69),ISBLANK(K69)<>TRUE),TRUE,FALSE) -> FALSE | T69: =IF(OR(AND(O69=G69,Q69=FALSE,R69=FALSE,S69=FALSE,G69<>"-"),AND(O69="Empate",S69=TRUE)),TRUE,FALSE) -> FALSE | U69: =IF(AND(Q69=FALSE,R69=FALSE,S69=FALSE,T69=FALSE),TRUE,FALSE) -> TRUE | W69: {=IF(OR(J69="Brasil",N69="Brasil"),2*_xlfn.IFS(Q69=TRUE,6,R69=TRUE,4,AND(S69=TRUE,T69=FALSE),3,T69=TRUE,2,U69=TRUE,0),_xlfn.IFS(Q69=TRUE,6,R69=TRUE,4,AND(S69=TRUE,T69=FALSE),3,T69=TRUE,2,U69=TRUE,0))} -> 0
A70: ='Tabela de Jogos'!A70 -> 68 | B70: ='Tabela de Jogos'!B70 -> Croácia | C70: ='Tabela de Jogos'!C70 -> 0 | D70: ='Tabela de Jogos'!D70 -> x | E70: ='Tabela de Jogos'!E70 -> 0 | F70: ='Tabela de Jogos'!F70 -> Gana | G70: ='Tabela de Jogos'!G70 -> - | I70: =A70 -> 68 | J70: =B70 -> Croácia | L70: =D70 -> x | N70: =F70 -> Gana | O70: =IF(K70>M70,J70,IF(M70>K70,N70,IF(ISBLANK(K70),"-","Empate"))) -> - | Q70: =IF(AND(O70=G70,K70=C70,M70=E70,ISBLANK(K70)<>TRUE),TRUE,FALSE) -> FALSE | R70: =IF(OR(AND(O70=G70,K70=C70,K70>M70,M70<>E70,ISBLANK(K70)<>TRUE),AND(O70=G70,M70>K70,K70<>C70,M70=E70,ISBLANK(K70)<>TRUE)),TRUE,FALSE) -> FALSE | S70: =IF(AND(O70=G70,ABS(K70-M70)=ABS(C70-E70),OR(K70<>C70,M70<>E70),ISBLANK(K70)<>TRUE),TRUE,FALSE) -> FALSE | T70: =IF(OR(AND(O70=G70,Q70=FALSE,R70=FALSE,S70=FALSE,G70<>"-"),AND(O70="Empate",S70=TRUE)),TRUE,FALSE) -> FALSE | U70: =IF(AND(Q70=FALSE,R70=FALSE,S70=FALSE,T70=FALSE),TRUE,FALSE) -> TRUE | W70: {=IF(OR(J70="Brasil",N70="Brasil"),2*_xlfn.IFS(Q70=TRUE,6,R70=TRUE,4,AND(S70=TRUE,T70=FALSE),3,T70=TRUE,2,U70=TRUE,0),_xlfn.IFS(Q70=TRUE,6,R70=TRUE,4,AND(S70=TRUE,T70=FALSE),3,T70=TRUE,2,U70=TRUE,0))} -> 0
A71: ='Tabela de Jogos'!A71 -> 69 | B71: ='Tabela de Jogos'!B71 -> Colômbia | C71: ='Tabela de Jogos'!C71 -> 0 | D71: ='Tabela de Jogos'!D71 -> x | E71: ='Tabela de Jogos'!E71 -> 0 | F71: ='Tabela de Jogos'!F71 -> Portugal | G71: ='Tabela de Jogos'!G71 -> - | I71: =A71 -> 69 | J71: =B71 -> Colômbia | L71: =D71 -> x | N71: =F71 -> Portugal | O71: =IF(K71>M71,J71,IF(M71>K71,N71,IF(ISBLANK(K71),"-","Empate"))) -> - | Q71: =IF(AND(O71=G71,K71=C71,M71=E71,ISBLANK(K71)<>TRUE),TRUE,FALSE) -> FALSE | R71: =IF(OR(AND(O71=G71,K71=C71,K71>M71,M71<>E71,ISBLANK(K71)<>TRUE),AND(O71=G71,M71>K71,K71<>C71,M71=E71,ISBLANK(K71)<>TRUE)),TRUE,FALSE) -> FALSE | S71: =IF(AND(O71=G71,ABS(K71-M71)=ABS(C71-E71),OR(K71<>C71,M71<>E71),ISBLANK(K71)<>TRUE),TRUE,FALSE) -> FALSE | T71: =IF(OR(AND(O71=G71,Q71=FALSE,R71=FALSE,S71=FALSE,G71<>"-"),AND(O71="Empate",S71=TRUE)),TRUE,FALSE) -> FALSE | U71: =IF(AND(Q71=FALSE,R71=FALSE,S71=FALSE,T71=FALSE),TRUE,FALSE) -> TRUE | W71: {=IF(OR(J71="Brasil",N71="Brasil"),2*_xlfn.IFS(Q71=TRUE,6,R71=TRUE,4,AND(S71=TRUE,T71=FALSE),3,T71=TRUE,2,U71=TRUE,0),_xlfn.IFS(Q71=TRUE,6,R71=TRUE,4,AND(S71=TRUE,T71=FALSE),3,T71=TRUE,2,U71=TRUE,0))} -> 0
A72: ='Tabela de Jogos'!A72 -> 70 | B72: ='Tabela de Jogos'!B72 -> RD Congo | C72: ='Tabela de Jogos'!C72 -> 0 | D72: ='Tabela de Jogos'!D72 -> x | E72: ='Tabela de Jogos'!E72 -> 0 | F72: ='Tabela de Jogos'!F72 -> Uzbequistão | G72: ='Tabela de Jogos'!G72 -> - | I72: =A72 -> 70 | J72: =B72 -> RD Congo | L72: =D72 -> x | N72: =F72 -> Uzbequistão | O72: =IF(K72>M72,J72,IF(M72>K72,N72,IF(ISBLANK(K72),"-","Empate"))) -> - | Q72: =IF(AND(O72=G72,K72=C72,M72=E72,ISBLANK(K72)<>TRUE),TRUE,FALSE) -> FALSE | R72: =IF(OR(AND(O72=G72,K72=C72,K72>M72,M72<>E72,ISBLANK(K72)<>TRUE),AND(O72=G72,M72>K72,K72<>C72,M72=E72,ISBLANK(K72)<>TRUE)),TRUE,FALSE) -> FALSE | S72: =IF(AND(O72=G72,ABS(K72-M72)=ABS(C72-E72),OR(K72<>C72,M72<>E72),ISBLANK(K72)<>TRUE),TRUE,FALSE) -> FALSE | T72: =IF(OR(AND(O72=G72,Q72=FALSE,R72=FALSE,S72=FALSE,G72<>"-"),AND(O72="Empate",S72=TRUE)),TRUE,FALSE) -> FALSE | U72: =IF(AND(Q72=FALSE,R72=FALSE,S72=FALSE,T72=FALSE),TRUE,FALSE) -> TRUE | W72: {=IF(OR(J72="Brasil",N72="Brasil"),2*_xlfn.IFS(Q72=TRUE,6,R72=TRUE,4,AND(S72=TRUE,T72=FALSE),3,T72=TRUE,2,U72=TRUE,0),_xlfn.IFS(Q72=TRUE,6,R72=TRUE,4,AND(S72=TRUE,T72=FALSE),3,T72=TRUE,2,U72=TRUE,0))} -> 0
A73: ='Tabela de Jogos'!A73 -> 71 | B73: ='Tabela de Jogos'!B73 -> Argélia | C73: ='Tabela de Jogos'!C73 -> 0 | D73: ='Tabela de Jogos'!D73 -> x | E73: ='Tabela de Jogos'!E73 -> 0 | F73: ='Tabela de Jogos'!F73 -> Áustria | G73: ='Tabela de Jogos'!G73 -> - | I73: =A73 -> 71 | J73: =B73 -> Argélia | L73: =D73 -> x | N73: =F73 -> Áustria | O73: =IF(K73>M73,J73,IF(M73>K73,N73,IF(ISBLANK(K73),"-","Empate"))) -> - | Q73: =IF(AND(O73=G73,K73=C73,M73=E73,ISBLANK(K73)<>TRUE),TRUE,FALSE) -> FALSE | R73: =IF(OR(AND(O73=G73,K73=C73,K73>M73,M73<>E73,ISBLANK(K73)<>TRUE),AND(O73=G73,M73>K73,K73<>C73,M73=E73,ISBLANK(K73)<>TRUE)),TRUE,FALSE) -> FALSE | S73: =IF(AND(O73=G73,ABS(K73-M73)=ABS(C73-E73),OR(K73<>C73,M73<>E73),ISBLANK(K73)<>TRUE),TRUE,FALSE) -> FALSE | T73: =IF(OR(AND(O73=G73,Q73=FALSE,R73=FALSE,S73=FALSE,G73<>"-"),AND(O73="Empate",S73=TRUE)),TRUE,FALSE) -> FALSE | U73: =IF(AND(Q73=FALSE,R73=FALSE,S73=FALSE,T73=FALSE),TRUE,FALSE) -> TRUE | W73: {=IF(OR(J73="Brasil",N73="Brasil"),2*_xlfn.IFS(Q73=TRUE,6,R73=TRUE,4,AND(S73=TRUE,T73=FALSE),3,T73=TRUE,2,U73=TRUE,0),_xlfn.IFS(Q73=TRUE,6,R73=TRUE,4,AND(S73=TRUE,T73=FALSE),3,T73=TRUE,2,U73=TRUE,0))} -> 0
A74: ='Tabela de Jogos'!A74 -> 72 | B74: ='Tabela de Jogos'!B74 -> Jordânia | C74: ='Tabela de Jogos'!C74 -> 0 | D74: ='Tabela de Jogos'!D74 -> x | E74: ='Tabela de Jogos'!E74 -> 0 | F74: ='Tabela de Jogos'!F74 -> Argentina | G74: ='Tabela de Jogos'!G74 -> - | I74: =A74 -> 72 | J74: =B74 -> Jordânia | L74: =D74 -> x | N74: =F74 -> Argentina | O74: =IF(K74>M74,J74,IF(M74>K74,N74,IF(ISBLANK(K74),"-","Empate"))) -> - | Q74: =IF(AND(O74=G74,K74=C74,M74=E74,ISBLANK(K74)<>TRUE),TRUE,FALSE) -> FALSE | R74: =IF(OR(AND(O74=G74,K74=C74,K74>M74,M74<>E74,ISBLANK(K74)<>TRUE),AND(O74=G74,M74>K74,K74<>C74,M74=E74,ISBLANK(K74)<>TRUE)),TRUE,FALSE) -> FALSE | S74: =IF(AND(O74=G74,ABS(K74-M74)=ABS(C74-E74),OR(K74<>C74,M74<>E74),ISBLANK(K74)<>TRUE),TRUE,FALSE) -> FALSE | T74: =IF(OR(AND(O74=G74,Q74=FALSE,R74=FALSE,S74=FALSE,G74<>"-"),AND(O74="Empate",S74=TRUE)),TRUE,FALSE) -> FALSE | U74: =IF(AND(Q74=FALSE,R74=FALSE,S74=FALSE,T74=FALSE),TRUE,FALSE) -> TRUE | W74: {=IF(OR(J74="Brasil",N74="Brasil"),2*_xlfn.IFS(Q74=TRUE,6,R74=TRUE,4,AND(S74=TRUE,T74=FALSE),3,T74=TRUE,2,U74=TRUE,0),_xlfn.IFS(Q74=TRUE,6,R74=TRUE,4,AND(S74=TRUE,T74=FALSE),3,T74=TRUE,2,U74=TRUE,0))} -> 0
... A106: ='Tabela de Jogos'!A106 -> 104 | B106: ='Tabela de Jogos'!B106 -> 0 | C106: ='Tabela de Jogos'!C106 -> 0 | D106: ='Tabela de Jogos'!D106 -> x | E106: ='Tabela de Jogos'!E106 -> 0 | F106: ='Tabela de Jogos'!F106 -> 0 | G106: ='Tabela de Jogos'!G106 -> - | I106: =A106 -> 104 | J106: =B106 -> 0 | L106: =D106 -> x | N106: =F106 -> 0 | O106: =IF(K106>M106,J106,IF(M106>K106,N106,IF(ISBLANK(K106),"-","Empate"))) -> - | Q106: =IF(AND(O106=G106,K106=C106,M106=E106,ISBLANK(K106)<>TRUE),TRUE,FALSE) -> FALSE | R106: =IF(OR(AND(O106=G106,K106=C106,K106>M106,M106<>E106,ISBLANK(K106)<>TRUE),AND(O106=G106,M106>K106,K106<>C106,M106=E106,ISBLANK(K106)<>TRUE)),TRUE,FALSE) -> FALSE | S106: =IF(AND(O106=G106,ABS(K106-M106)=ABS(C106-E106),OR(K106<>C106,M106<>E106),ISBLANK(K106)<>TRUE),TRUE,FALSE) -> FALSE | T106: =IF(OR(AND(O106=G106,Q106=FALSE,R106=FALSE,S106=FALSE,G106<>"-"),AND(O106="Empate",S106=TRUE)),TRUE,FALSE) -> FALSE | U106: =IF(AND(Q106=FALSE,R106=FALSE,S106=FALSE,T106=FALSE),TRUE,FALSE) -> TRUE | W106: {=IF(OR(J106="Brasil",N106="Brasil"),2*_xlfn.IFS(Q106=TRUE,6,R106=TRUE,4,AND(S106=TRUE,T106=FALSE),3,T106=TRUE,2,U106=TRUE,0),_xlfn.IFS(Q106=TRUE,6,R106=TRUE,4,AND(S106=TRUE,T106=FALSE),3,T106=TRUE,2,U106=TRUE,0))} -> 0

Sheet Arthur
A1: ='Tabela de Jogos'!A1 -> Tabela de Jogos | I1: Palpites
A2: ='Tabela de Jogos'!A2 -> Jogo | B2: ='Tabela de Jogos'!B2 -> Seleção A | C2: ='Tabela de Jogos'!C2 -> Gols A | D2: ='Tabela de Jogos'!D2 -> x | E2: ='Tabela de Jogos'!E2 -> Gols B | F2: ='Tabela de Jogos'!F2 -> Seleção B | G2: ='Tabela de Jogos'!G2 -> Vencedor | I2: =A2 -> Jogo | J2: =B2 -> Seleção A | K2: =C2 -> Gols A | L2: =D2 -> x | M2: =E2 -> Gols B | N2: =F2 -> Seleção B | O2: Vencedor | Q2: 6 pontos | R2: 4 pontos | S2: 3 pontos | T2: 2 pontos | U2: 0 pontos | W2: Pontos | X2: Total | Y2: Total de Acertos
A3: ='Tabela de Jogos'!A3 -> 1 | B3: ='Tabela de Jogos'!B3 -> México | C3: ='Tabela de Jogos'!C3 -> 2 | D3: ='Tabela de Jogos'!D3 -> x | E3: ='Tabela de Jogos'!E3 -> 0 | F3: ='Tabela de Jogos'!F3 -> África do Sul | G3: ='Tabela de Jogos'!G3 -> México | I3: =A3 -> 1 | J3: =B3 -> México | K3: 2 | L3: =D3 -> x | M3: 1 | N3: =F3 -> África do Sul | O3: =IF(K3>M3,J3,IF(M3>K3,N3,IF(ISBLANK(K3),"-","Empate"))) -> México | Q3: =IF(AND(O3=G3,K3=C3,M3=E3,ISBLANK(K3)<>TRUE),TRUE,FALSE) -> FALSE | R3: =IF(OR(AND(O3=G3,K3=C3,K3>M3,M3<>E3,ISBLANK(K3)<>TRUE),AND(O3=G3,M3>K3,K3<>C3,M3=E3,ISBLANK(K3)<>TRUE)),TRUE,FALSE) -> TRUE | S3: =IF(AND(O3=G3,ABS(K3-M3)=ABS(C3-E3),OR(K3<>C3,M3<>E3),ISBLANK(K3)<>TRUE),TRUE,FALSE) -> FALSE | T3: =IF(OR(AND(O3=G3,Q3=FALSE,R3=FALSE,S3=FALSE,G3<>"-"),AND(O3="Empate",S3=TRUE)),TRUE,FALSE) -> FALSE | U3: =IF(AND(Q3=FALSE,R3=FALSE,S3=FALSE,T3=FALSE),TRUE,FALSE) -> FALSE | W3: {=IF(OR(J3="Brasil",N3="Brasil"),2*_xlfn.IFS(Q3=TRUE,6,R3=TRUE,4,AND(S3=TRUE,T3=FALSE),3,T3=TRUE,2,U3=TRUE,0),_xlfn.IFS(Q3=TRUE,6,R3=TRUE,4,AND(S3=TRUE,T3=FALSE),3,T3=TRUE,2,U3=TRUE,0))} -> 4 | X3: =SUM(W3:W106) -> 107 | Y3: =COUNTIF(W3:W106,6)+COUNTIF(W3:W106,12) -> 4
A4: ='Tabela de Jogos'!A4 -> 2 | B4: ='Tabela de Jogos'!B4 -> Coreia do Sul | C4: ='Tabela de Jogos'!C4 -> 2 | D4: ='Tabela de Jogos'!D4 -> x | E4: ='Tabela de Jogos'!E4 -> 1 | F4: ='Tabela de Jogos'!F4 -> Tchéquia | G4: ='Tabela de Jogos'!G4 -> Coreia do Sul | I4: =A4 -> 2 | J4: =B4 -> Coreia do Sul | K4: 2 | L4: =D4 -> x | M4: 0 | N4: =F4 -> Tchéquia | O4: =IF(K4>M4,J4,IF(M4>K4,N4,IF(ISBLANK(K4),"-","Empate"))) -> Coreia do Sul | Q4: =IF(AND(O4=G4,K4=C4,M4=E4,ISBLANK(K4)<>TRUE),TRUE,FALSE) -> FALSE | R4: =IF(OR(AND(O4=G4,K4=C4,K4>M4,M4<>E4,ISBLANK(K4)<>TRUE),AND(O4=G4,M4>K4,K4<>C4,M4=E4,ISBLANK(K4)<>TRUE)),TRUE,FALSE) -> TRUE | S4: =IF(AND(O4=G4,ABS(K4-M4)=ABS(C4-E4),OR(K4<>C4,M4<>E4),ISBLANK(K4)<>TRUE),TRUE,FALSE) -> FALSE | T4: =IF(OR(AND(O4=G4,Q4=FALSE,R4=FALSE,S4=FALSE,G4<>"-"),AND(O4="Empate",S4=TRUE)),TRUE,FALSE) -> FALSE | U4: =IF(AND(Q4=FALSE,R4=FALSE,S4=FALSE,T4=FALSE),TRUE,FALSE) -> FALSE | W4: {=IF(OR(J4="Brasil",N4="Brasil"),2*_xlfn.IFS(Q4=TRUE,6,R4=TRUE,4,AND(S4=TRUE,T4=FALSE),3,T4=TRUE,2,U4=TRUE,0),_xlfn.IFS(Q4=TRUE,6,R4=TRUE,4,AND(S4=TRUE,T4=FALSE),3,T4=TRUE,2,U4=TRUE,0))} -> 4
A5: ='Tabela de Jogos'!A5 -> 3 | B5: ='Tabela de Jogos'!B5 -> Canadá | C5: ='Tabela de Jogos'!C5 -> 1 | D5: ='Tabela de Jogos'!D5 -> x | E5: ='Tabela de Jogos'!E5 -> 1 | F5: ='Tabela de Jogos'!F5 -> Bósnia | G5: ='Tabela de Jogos'!G5 -> Empate | I5: =A5 -> 3 | J5: =B5 -> Canadá | K5: 0 | L5: =D5 -> x | M5: 2 | N5: =F5 -> Bósnia | O5: =IF(K5>M5,J5,IF(M5>K5,N5,IF(ISBLANK(K5),"-","Empate"))) -> Bósnia | Q5: =IF(AND(O5=G5,K5=C5,M5=E5,ISBLANK(K5)<>TRUE),TRUE,FALSE) -> FALSE | R5: =IF(OR(AND(O5=G5,K5=C5,K5>M5,M5<>E5,ISBLANK(K5)<>TRUE),AND(O5=G5,M5>K5,K5<>C5,M5=E5,ISBLANK(K5)<>TRUE)),TRUE,FALSE) -> FALSE | S5: =IF(AND(O5=G5,ABS(K5-M5)=ABS(C5-E5),OR(K5<>C5,M5<>E5),ISBLANK(K5)<>TRUE),TRUE,FALSE) -> FALSE | T5: =IF(OR(AND(O5=G5,Q5=FALSE,R5=FALSE,S5=FALSE,G5<>"-"),AND(O5="Empate",S5=TRUE)),TRUE,FALSE) -> FALSE | U5: =IF(AND(Q5=FALSE,R5=FALSE,S5=FALSE,T5=FALSE),TRUE,FALSE) -> TRUE | W5: {=IF(OR(J5="Brasil",N5="Brasil"),2*_xlfn.IFS(Q5=TRUE,6,R5=TRUE,4,AND(S5=TRUE,T5=FALSE),3,T5=TRUE,2,U5=TRUE,0),_xlfn.IFS(Q5=TRUE,6,R5=TRUE,4,AND(S5=TRUE,T5=FALSE),3,T5=TRUE,2,U5=TRUE,0))} -> 0
A6: ='Tabela de Jogos'!A6 -> 4 | B6: ='Tabela de Jogos'!B6 -> EUA | C6: ='Tabela de Jogos'!C6 -> 4 | D6: ='Tabela de Jogos'!D6 -> x | E6: ='Tabela de Jogos'!E6 -> 1 | F6: ='Tabela de Jogos'!F6 -> Paraguai | G6: ='Tabela de Jogos'!G6 -> EUA | I6: =A6 -> 4 | J6: =B6 -> EUA | K6: 1 | L6: =D6 -> x | M6: 0 | N6: =F6 -> Paraguai | O6: =IF(K6>M6,J6,IF(M6>K6,N6,IF(ISBLANK(K6),"-","Empate"))) -> EUA | Q6: =IF(AND(O6=G6,K6=C6,M6=E6,ISBLANK(K6)<>TRUE),TRUE,FALSE) -> FALSE | R6: =IF(OR(AND(O6=G6,K6=C6,K6>M6,M6<>E6,ISBLANK(K6)<>TRUE),AND(O6=G6,M6>K6,K6<>C6,M6=E6,ISBLANK(K6)<>TRUE)),TRUE,FALSE) -> FALSE | S6: =IF(AND(O6=G6,ABS(K6-M6)=ABS(C6-E6),OR(K6<>C6,M6<>E6),ISBLANK(K6)<>TRUE),TRUE,FALSE) -> FALSE | T6: =IF(OR(AND(O6=G6,Q6=FALSE,R6=FALSE,S6=FALSE,G6<>"-"),AND(O6="Empate",S6=TRUE)),TRUE,FALSE) -> TRUE | U6: =IF(AND(Q6=FALSE,R6=FALSE,S6=FALSE,T6=FALSE),TRUE,FALSE) -> FALSE | W6: {=IF(OR(J6="Brasil",N6="Brasil"),2*_xlfn.IFS(Q6=TRUE,6,R6=TRUE,4,AND(S6=TRUE,T6=FALSE),3,T6=TRUE,2,U6=TRUE,0),_xlfn.IFS(Q6=TRUE,6,R6=TRUE,4,AND(S6=TRUE,T6=FALSE),3,T6=TRUE,2,U6=TRUE,0))} -> 2
A7: ='Tabela de Jogos'!A7 -> 5 | B7: ='Tabela de Jogos'!B7 -> Catar | C7: ='Tabela de Jogos'!C7 -> 1 | D7: ='Tabela de Jogos'!D7 -> x | E7: ='Tabela de Jogos'!E7 -> 1 | F7: ='Tabela de Jogos'!F7 -> Suíça | G7: ='Tabela de Jogos'!G7 -> Empate | I7: =A7 -> 5 | J7: =B7 -> Catar | K7: 0 | L7: =D7 -> x | M7: 3 | N7: =F7 -> Suíça | O7: =IF(K7>M7,J7,IF(M7>K7,N7,IF(ISBLANK(K7),"-","Empate"))) -> Suíça | Q7: =IF(AND(O7=G7,K7=C7,M7=E7,ISBLANK(K7)<>TRUE),TRUE,FALSE) -> FALSE | R7: =IF(OR(AND(O7=G7,K7=C7,K7>M7,M7<>E7,ISBLANK(K7)<>TRUE),AND(O7=G7,M7>K7,K7<>C7,M7=E7,ISBLANK(K7)<>TRUE)),TRUE,FALSE) -> FALSE | S7: =IF(AND(O7=G7,ABS(K7-M7)=ABS(C7-E7),OR(K7<>C7,M7<>E7),ISBLANK(K7)<>TRUE),TRUE,FALSE) -> FALSE | T7: =IF(OR(AND(O7=G7,Q7=FALSE,R7=FALSE,S7=FALSE,G7<>"-"),AND(O7="Empate",S7=TRUE)),TRUE,FALSE) -> FALSE | U7: =IF(AND(Q7=FALSE,R7=FALSE,S7=FALSE,T7=FALSE),TRUE,FALSE) -> TRUE | W7: {=IF(OR(J7="Brasil",N7="Brasil"),2*_xlfn.IFS(Q7=TRUE,6,R7=TRUE,4,AND(S7=TRUE,T7=FALSE),3,T7=TRUE,2,U7=TRUE,0),_xlfn.IFS(Q7=TRUE,6,R7=TRUE,4,AND(S7=TRUE,T7=FALSE),3,T7=TRUE,2,U7=TRUE,0))} -> 0
A8: ='Tabela de Jogos'!A8 -> 6 | B8: ='Tabela de Jogos'!B8 -> Brasil | C8: ='Tabela de Jogos'!C8 -> 1 | D8: ='Tabela de Jogos'!D8 -> x | E8: ='Tabela de Jogos'!E8 -> 1 | F8: ='Tabela de Jogos'!F8 -> Marrocos | G8: ='Tabela de Jogos'!G8 -> Empate | I8: =A8 -> 6 | J8: =B8 -> Brasil | K8: 2 | L8: =D8 -> x | M8: 1 | N8: =F8 -> Marrocos | O8: =IF(K8>M8,J8,IF(M8>K8,N8,IF(ISBLANK(K8),"-","Empate"))) -> Brasil | Q8: =IF(AND(O8=G8,K8=C8,M8=E8,ISBLANK(K8)<>TRUE),TRUE,FALSE) -> FALSE | R8: =IF(OR(AND(O8=G8,K8=C8,K8>M8,M8<>E8,ISBLANK(K8)<>TRUE),AND(O8=G8,M8>K8,K8<>C8,M8=E8,ISBLANK(K8)<>TRUE)),TRUE,FALSE) -> FALSE | S8: =IF(AND(O8=G8,ABS(K8-M8)=ABS(C8-E8),OR(K8<>C8,M8<>E8),ISBLANK(K8)<>TRUE),TRUE,FALSE) -> FALSE | T8: =IF(OR(AND(O8=G8,Q8=FALSE,R8=FALSE,S8=FALSE,G8<>"-"),AND(O8="Empate",S8=TRUE)),TRUE,FALSE) -> FALSE | U8: =IF(AND(Q8=FALSE,R8=FALSE,S8=FALSE,T8=FALSE),TRUE,FALSE) -> TRUE | W8: {=IF(OR(J8="Brasil",N8="Brasil"),2*_xlfn.IFS(Q8=TRUE,6,R8=TRUE,4,AND(S8=TRUE,T8=FALSE),3,T8=TRUE,2,U8=TRUE,0),_xlfn.IFS(Q8=TRUE,6,R8=TRUE,4,AND(S8=TRUE,T8=FALSE),3,T8=TRUE,2,U8=TRUE,0))} -> 0
A9: ='Tabela de Jogos'!A9 -> 7 | B9: ='Tabela de Jogos'!B9 -> Haiti | C9: ='Tabela de Jogos'!C9 -> 0 | D9: ='Tabela de Jogos'!D9 -> x | E9: ='Tabela de Jogos'!E9 -> 1 | F9: ='Tabela de Jogos'!F9 -> Escócia | G9: ='Tabela de Jogos'!G9 -> Escócia | I9: =A9 -> 7 | J9: =B9 -> Haiti | K9: 1 | L9: =D9 -> x | M9: 3 | N9: =F9 -> Escócia | O9: =IF(K9>M9,J9,IF(M9>K9,N9,IF(ISBLANK(K9),"-","Empate"))) -> Escócia | Q9: =IF(AND(O9=G9,K9=C9,M9=E9,ISBLANK(K9)<>TRUE),TRUE,FALSE) -> FALSE | R9: =IF(OR(AND(O9=G9,K9=C9,K9>M9,M9<>E9,ISBLANK(K9)<>TRUE),AND(O9=G9,M9>K9,K9<>C9,M9=E9,ISBLANK(K9)<>TRUE)),TRUE,FALSE) -> FALSE | S9: =IF(AND(O9=G9,ABS(K9-M9)=ABS(C9-E9),OR(K9<>C9,M9<>E9),ISBLANK(K9)<>TRUE),TRUE,FALSE) -> FALSE | T9: =IF(OR(AND(O9=G9,Q9=FALSE,R9=FALSE,S9=FALSE,G9<>"-"),AND(O9="Empate",S9=TRUE)),TRUE,FALSE) -> TRUE | U9: =IF(AND(Q9=FALSE,R9=FALSE,S9=FALSE,T9=FALSE),TRUE,FALSE) -> FALSE | W9: {=IF(OR(J9="Brasil",N9="Brasil"),2*_xlfn.IFS(Q9=TRUE,6,R9=TRUE,4,AND(S9=TRUE,T9=FALSE),3,T9=TRUE,2,U9=TRUE,0),_xlfn.IFS(Q9=TRUE,6,R9=TRUE,4,AND(S9=TRUE,T9=FALSE),3,T9=TRUE,2,U9=TRUE,0))} -> 2
A10: ='Tabela de Jogos'!A10 -> 8 | B10: ='Tabela de Jogos'!B10 -> Austrália | C10: ='Tabela de Jogos'!C10 -> 2 | D10: ='Tabela de Jogos'!D10 -> x | E10: ='Tabela de Jogos'!E10 -> 0 | F10: ='Tabela de Jogos'!F10 -> Turquia | G10: ='Tabela de Jogos'!G10 -> Austrália | I10: =A10 -> 8 | J10: =B10 -> Austrália | K10: 1 | L10: =D10 -> x | M10: 2 | N10: =F10 -> Turquia | O10: =IF(K10>M10,J10,IF(M10>K10,N10,IF(ISBLANK(K10),"-","Empate"))) -> Turquia | Q10: =IF(AND(O10=G10,K10=C10,M10=E10,ISBLANK(K10)<>TRUE),TRUE,FALSE) -> FALSE | R10: =IF(OR(AND(O10=G10,K10=C10,K10>M10,M10<>E10,ISBLANK(K10)<>TRUE),AND(O10=G10,M10>K10,K10<>C10,M10=E10,ISBLANK(K10)<>TRUE)),TRUE,FALSE) -> FALSE | S10: =IF(AND(O10=G10,ABS(K10-M10)=ABS(C10-E10),OR(K10<>C10,M10<>E10),ISBLANK(K10)<>TRUE),TRUE,FALSE) -> FALSE | T10: =IF(OR(AND(O10=G10,Q10=FALSE,R10=FALSE,S10=FALSE,G10<>"-"),AND(O10="Empate",S10=TRUE)),TRUE,FALSE) -> FALSE | U10: =IF(AND(Q10=FALSE,R10=FALSE,S10=FALSE,T10=FALSE),TRUE,FALSE) -> TRUE | W10: {=IF(OR(J10="Brasil",N10="Brasil"),2*_xlfn.IFS(Q10=TRUE,6,R10=TRUE,4,AND(S10=TRUE,T10=FALSE),3,T10=TRUE,2,U10=TRUE,0),_xlfn.IFS(Q10=TRUE,6,R10=TRUE,4,AND(S10=TRUE,T10=FALSE),3,T10=TRUE,2,U10=TRUE,0))} -> 0
A11: ='Tabela de Jogos'!A11 -> 9 | B11: ='Tabela de Jogos'!B11 -> Alemanha | C11: ='Tabela de Jogos'!C11 -> 7 | D11: ='Tabela de Jogos'!D11 -> x | E11: ='Tabela de Jogos'!E11 -> 1 | F11: ='Tabela de Jogos'!F11 -> Curaçao | G11: ='Tabela de Jogos'!G11 -> Alemanha | I11: =A11 -> 9 | J11: =B11 -> Alemanha | K11: 4 | L11: =D11 -> x | M11: 0 | N11: =F11 -> Curaçao | O11: =IF(K11>M11,J11,IF(M11>K11,N11,IF(ISBLANK(K11),"-","Empate"))) -> Alemanha | Q11: =IF(AND(O11=G11,K11=C11,M11=E11,ISBLANK(K11)<>TRUE),TRUE,FALSE) -> FALSE | R11: =IF(OR(AND(O11=G11,K11=C11,K11>M11,M11<>E11,ISBLANK(K11)<>TRUE),AND(O11=G11,M11>K11,K11<>C11,M11=E11,ISBLANK(K11)<>TRUE)),TRUE,FALSE) -> FALSE | S11: =IF(AND(O11=G11,ABS(K11-M11)=ABS(C11-E11),OR(K11<>C11,M11<>E11),ISBLANK(K11)<>TRUE),TRUE,FALSE) -> FALSE | T11: =IF(OR(AND(O11=G11,Q11=FALSE,R11=FALSE,S11=FALSE,G11<>"-"),AND(O11="Empate",S11=TRUE)),TRUE,FALSE) -> TRUE | U11: =IF(AND(Q11=FALSE,R11=FALSE,S11=FALSE,T11=FALSE),TRUE,FALSE) -> FALSE | W11: {=IF(OR(J11="Brasil",N11="Brasil"),2*_xlfn.IFS(Q11=TRUE,6,R11=TRUE,4,AND(S11=TRUE,T11=FALSE),3,T11=TRUE,2,U11=TRUE,0),_xlfn.IFS(Q11=TRUE,6,R11=TRUE,4,AND(S11=TRUE,T11=FALSE),3,T11=TRUE,2,U11=TRUE,0))} -> 2
A12: ='Tabela de Jogos'!A12 -> 10 | B12: ='Tabela de Jogos'!B12 -> Holanda | C12: ='Tabela de Jogos'!C12 -> 2 | D12: ='Tabela de Jogos'!D12 -> x | E12: ='Tabela de Jogos'!E12 -> 2 | F12: ='Tabela de Jogos'!F12 -> Japão | G12: ='Tabela de Jogos'!G12 -> Empate | I12: =A12 -> 10 | J12: =B12 -> Holanda | K12: 2 | L12: =D12 -> x | M12: 1 | N12: =F12 -> Japão | O12: =IF(K12>M12,J12,IF(M12>K12,N12,IF(ISBLANK(K12),"-","Empate"))) -> Holanda | Q12: =IF(AND(O12=G12,K12=C12,M12=E12,ISBLANK(K12)<>TRUE),TRUE,FALSE) -> FALSE | R12: =IF(OR(AND(O12=G12,K12=C12,K12>M12,M12<>E12,ISBLANK(K12)<>TRUE),AND(O12=G12,M12>K12,K12<>C12,M12=E12,ISBLANK(K12)<>TRUE)),TRUE,FALSE) -> FALSE | S12: =IF(AND(O12=G12,ABS(K12-M12)=ABS(C12-E12),OR(K12<>C12,M12<>E12),ISBLANK(K12)<>TRUE),TRUE,FALSE) -> FALSE | T12: =IF(OR(AND(O12=G12,Q12=FALSE,R12=FALSE,S12=FALSE,G12<>"-"),AND(O12="Empate",S12=TRUE)),TRUE,FALSE) -> FALSE | U12: =IF(AND(Q12=FALSE,R12=FALSE,S12=FALSE,T12=FALSE),TRUE,FALSE) -> TRUE | W12: {=IF(OR(J12="Brasil",N12="Brasil"),2*_xlfn.IFS(Q12=TRUE,6,R12=TRUE,4,AND(S12=TRUE,T12=FALSE),3,T12=TRUE,2,U12=TRUE,0),_xlfn.IFS(Q12=TRUE,6,R12=TRUE,4,AND(S12=TRUE,T12=FALSE),3,T12=TRUE,2,U12=TRUE,0))} -> 0
A13: ='Tabela de Jogos'!A13 -> 11 | B13: ='Tabela de Jogos'!B13 -> Costa do Marfim | C13: ='Tabela de Jogos'!C13 -> 1 | D13: ='Tabela de Jogos'!D13 -> x | E13: ='Tabela de Jogos'!E13 -> 0 | F13: ='Tabela de Jogos'!F13 -> Equador | G13: ='Tabela de Jogos'!G13 -> Costa do Marfim | I13: =A13 -> 11 | J13: =B13 -> Costa do Marfim | K13: 0 | L13: =D13 -> x | M13: 2 | N13: =F13 -> Equador | O13: =IF(K13>M13,J13,IF(M13>K13,N13,IF(ISBLANK(K13),"-","Empate"))) -> Equador | Q13: =IF(AND(O13=G13,K13=C13,M13=E13,ISBLANK(K13)<>TRUE),TRUE,FALSE) -> FALSE | R13: =IF(OR(AND(O13=G13,K13=C13,K13>M13,M13<>E13,ISBLANK(K13)<>TRUE),AND(O13=G13,M13>K13,K13<>C13,M13=E13,ISBLANK(K13)<>TRUE)),TRUE,FALSE) -> FALSE | S13: =IF(AND(O13=G13,ABS(K13-M13)=ABS(C13-E13),OR(K13<>C13,M13<>E13),ISBLANK(K13)<>TRUE),TRUE,FALSE) -> FALSE | T13: =IF(OR(AND(O13=G13,Q13=FALSE,R13=FALSE,S13=FALSE,G13<>"-"),AND(O13="Empate",S13=TRUE)),TRUE,FALSE) -> FALSE | U13: =IF(AND(Q13=FALSE,R13=FALSE,S13=FALSE,T13=FALSE),TRUE,FALSE) -> TRUE | W13: {=IF(OR(J13="Brasil",N13="Brasil"),2*_xlfn.IFS(Q13=TRUE,6,R13=TRUE,4,AND(S13=TRUE,T13=FALSE),3,T13=TRUE,2,U13=TRUE,0),_xlfn.IFS(Q13=TRUE,6,R13=TRUE,4,AND(S13=TRUE,T13=FALSE),3,T13=TRUE,2,U13=TRUE,0))} -> 0
A14: ='Tabela de Jogos'!A14 -> 12 | B14: ='Tabela de Jogos'!B14 -> Suécia | C14: ='Tabela de Jogos'!C14 -> 5 | D14: ='Tabela de Jogos'!D14 -> x | E14: ='Tabela de Jogos'!E14 -> 1 | F14: ='Tabela de Jogos'!F14 -> Tunísia | G14: ='Tabela de Jogos'!G14 -> Suécia | I14: =A14 -> 12 | J14: =B14 -> Suécia | K14: 1 | L14: =D14 -> x | M14: 0 | N14: =F14 -> Tunísia | O14: =IF(K14>M14,J14,IF(M14>K14,N14,IF(ISBLANK(K14),"-","Empate"))) -> Suécia | Q14: =IF(AND(O14=G14,K14=C14,M14=E14,ISBLANK(K14)<>TRUE),TRUE,FALSE) -> FALSE | R14: =IF(OR(AND(O14=G14,K14=C14,K14>M14,M14<>E14,ISBLANK(K14)<>TRUE),AND(O14=G14,M14>K14,K14<>C14,M14=E14,ISBLANK(K14)<>TRUE)),TRUE,FALSE) -> FALSE | S14: =IF(AND(O14=G14,ABS(K14-M14)=ABS(C14-E14),OR(K14<>C14,M14<>E14),ISBLANK(K14)<>TRUE),TRUE,FALSE) -> FALSE | T14: =IF(OR(AND(O14=G14,Q14=FALSE,R14=FALSE,S14=FALSE,G14<>"-"),AND(O14="Empate",S14=TRUE)),TRUE,FALSE) -> TRUE | U14: =IF(AND(Q14=FALSE,R14=FALSE,S14=FALSE,T14=FALSE),TRUE,FALSE) -> FALSE | W14: {=IF(OR(J14="Brasil",N14="Brasil"),2*_xlfn.IFS(Q14=TRUE,6,R14=TRUE,4,AND(S14=TRUE,T14=FALSE),3,T14=TRUE,2,U14=TRUE,0),_xlfn.IFS(Q14=TRUE,6,R14=TRUE,4,AND(S14=TRUE,T14=FALSE),3,T14=TRUE,2,U14=TRUE,0))} -> 2
A15: ='Tabela de Jogos'!A15 -> 13 | B15: ='Tabela de Jogos'!B15 -> Espanha | C15: ='Tabela de Jogos'!C15 -> 0 | D15: ='Tabela de Jogos'!D15 -> x | E15: ='Tabela de Jogos'!E15 -> 0 | F15: ='Tabela de Jogos'!F15 -> Cabo Verde | G15: ='Tabela de Jogos'!G15 -> Empate | I15: =A15 -> 13 | J15: =B15 -> Espanha | K15: 5 | L15: =D15 -> x | M15: 0 | N15: =F15 -> Cabo Verde | O15: =IF(K15>M15,J15,IF(M15>K15,N15,IF(ISBLANK(K15),"-","Empate"))) -> Espanha | Q15: =IF(AND(O15=G15,K15=C15,M15=E15,ISBLANK(K15)<>TRUE),TRUE,FALSE) -> FALSE | R15: =IF(OR(AND(O15=G15,K15=C15,K15>M15,M15<>E15,ISBLANK(K15)<>TRUE),AND(O15=G15,M15>K15,K15<>C15,M15=E15,ISBLANK(K15)<>TRUE)),TRUE,FALSE) -> FALSE | S15: =IF(AND(O15=G15,ABS(K15-M15)=ABS(C15-E15),OR(K15<>C15,M15<>E15),ISBLANK(K15)<>TRUE),TRUE,FALSE) -> FALSE | T15: =IF(OR(AND(O15=G15,Q15=FALSE,R15=FALSE,S15=FALSE,G15<>"-"),AND(O15="Empate",S15=TRUE)),TRUE,FALSE) -> FALSE | U15: =IF(AND(Q15=FALSE,R15=FALSE,S15=FALSE,T15=FALSE),TRUE,FALSE) -> TRUE | W15: {=IF(OR(J15="Brasil",N15="Brasil"),2*_xlfn.IFS(Q15=TRUE,6,R15=TRUE,4,AND(S15=TRUE,T15=FALSE),3,T15=TRUE,2,U15=TRUE,0),_xlfn.IFS(Q15=TRUE,6,R15=TRUE,4,AND(S15=TRUE,T15=FALSE),3,T15=TRUE,2,U15=TRUE,0))} -> 0
... A62: ='Tabela de Jogos'!A62 -> 60 | B62: ='Tabela de Jogos'!B62 -> Paraguai | C62: ='Tabela de Jogos'!C62 -> 0 | D62: ='Tabela de Jogos'!D62 -> x | E62: ='Tabela de Jogos'!E62 -> 0 | F62: ='Tabela de Jogos'!F62 -> Austrália | G62: ='Tabela de Jogos'!G62 -> - | I62: =A62 -> 60 | J62: =B62 -> Paraguai | K62: 2 | L62: =D62 -> x | M62: 1 | N62: =F62 -> Austrália | O62: =IF(K62>M62,J62,IF(M62>K62,N62,IF(ISBLANK(K62),"-","Empate"))) -> Paraguai | Q62: =IF(AND(O62=G62,K62=C62,M62=E62,ISBLANK(K62)<>TRUE),TRUE,FALSE) -> FALSE | R62: =IF(OR(AND(O62=G62,K62=C62,K62>M62,M62<>E62,ISBLANK(K62)<>TRUE),AND(O62=G62,M62>K62,K62<>C62,M62=E62,ISBLANK(K62)<>TRUE)),TRUE,FALSE) -> FALSE | S62: =IF(AND(O62=G62,ABS(K62-M62)=ABS(C62-E62),OR(K62<>C62,M62<>E62),ISBLANK(K62)<>TRUE),TRUE,FALSE) -> FALSE | T62: =IF(OR(AND(O62=G62,Q62=FALSE,R62=FALSE,S62=FALSE,G62<>"-"),AND(O62="Empate",S62=TRUE)),TRUE,FALSE) -> FALSE | U62: =IF(AND(Q62=FALSE,R62=FALSE,S62=FALSE,T62=FALSE),TRUE,FALSE) -> TRUE | W62: {=IF(OR(J62="Brasil",N62="Brasil"),2*_xlfn.IFS(Q62=TRUE,6,R62=TRUE,4,AND(S62=TRUE,T62=FALSE),3,T62=TRUE,2,U62=TRUE,0),_xlfn.IFS(Q62=TRUE,6,R62=TRUE,4,AND(S62=TRUE,T62=FALSE),3,T62=TRUE,2,U62=TRUE,0))} -> 0
A63: ='Tabela de Jogos'!A63 -> 61 | B63: ='Tabela de Jogos'!B63 -> Noruega | C63: ='Tabela de Jogos'!C63 -> 0 | D63: ='Tabela de Jogos'!D63 -> x | E63: ='Tabela de Jogos'!E63 -> 0 | F63: ='Tabela de Jogos'!F63 -> França | G63: ='Tabela de Jogos'!G63 -> - | I63: =A63 -> 61 | J63: =B63 -> Noruega | L63: =D63 -> x | N63: =F63 -> França | O63: =IF(K63>M63,J63,IF(M63>K63,N63,IF(ISBLANK(K63),"-","Empate"))) -> - | Q63: =IF(AND(O63=G63,K63=C63,M63=E63,ISBLANK(K63)<>TRUE),TRUE,FALSE) -> FALSE | R63: =IF(OR(AND(O63=G63,K63=C63,K63>M63,M63<>E63,ISBLANK(K63)<>TRUE),AND(O63=G63,M63>K63,K63<>C63,M63=E63,ISBLANK(K63)<>TRUE)),TRUE,FALSE) -> FALSE | S63: =IF(AND(O63=G63,ABS(K63-M63)=ABS(C63-E63),OR(K63<>C63,M63<>E63),ISBLANK(K63)<>TRUE),TRUE,FALSE) -> FALSE | T63: =IF(OR(AND(O63=G63,Q63=FALSE,R63=FALSE,S63=FALSE,G63<>"-"),AND(O63="Empate",S63=TRUE)),TRUE,FALSE) -> FALSE | U63: =IF(AND(Q63=FALSE,R63=FALSE,S63=FALSE,T63=FALSE),TRUE,FALSE) -> TRUE | W63: {=IF(OR(J63="Brasil",N63="Brasil"),2*_xlfn.IFS(Q63=TRUE,6,R63=TRUE,4,AND(S63=TRUE,T63=FALSE),3,T63=TRUE,2,U63=TRUE,0),_xlfn.IFS(Q63=TRUE,6,R63=TRUE,4,AND(S63=TRUE,T63=FALSE),3,T63=TRUE,2,U63=TRUE,0))} -> 0
A64: ='Tabela de Jogos'!A64 -> 62 | B64: ='Tabela de Jogos'!B64 -> Senegal | C64: ='Tabela de Jogos'!C64 -> 0 | D64: ='Tabela de Jogos'!D64 -> x | E64: ='Tabela de Jogos'!E64 -> 0 | F64: ='Tabela de Jogos'!F64 -> Iraque | G64: ='Tabela de Jogos'!G64 -> - | I64: =A64 -> 62 | J64: =B64 -> Senegal | L64: =D64 -> x | N64: =F64 -> Iraque | O64: =IF(K64>M64,J64,IF(M64>K64,N64,IF(ISBLANK(K64),"-","Empate"))) -> - | Q64: =IF(AND(O64=G64,K64=C64,M64=E64,ISBLANK(K64)<>TRUE),TRUE,FALSE) -> FALSE | R64: =IF(OR(AND(O64=G64,K64=C64,K64>M64,M64<>E64,ISBLANK(K64)<>TRUE),AND(O64=G64,M64>K64,K64<>C64,M64=E64,ISBLANK(K64)<>TRUE)),TRUE,FALSE) -> FALSE | S64: =IF(AND(O64=G64,ABS(K64-M64)=ABS(C64-E64),OR(K64<>C64,M64<>E64),ISBLANK(K64)<>TRUE),TRUE,FALSE) -> FALSE | T64: =IF(OR(AND(O64=G64,Q64=FALSE,R64=FALSE,S64=FALSE,G64<>"-"),AND(O64="Empate",S64=TRUE)),TRUE,FALSE) -> FALSE | U64: =IF(AND(Q64=FALSE,R64=FALSE,S64=FALSE,T64=FALSE),TRUE,FALSE) -> TRUE | W64: {=IF(OR(J64="Brasil",N64="Brasil"),2*_xlfn.IFS(Q64=TRUE,6,R64=TRUE,4,AND(S64=TRUE,T64=FALSE),3,T64=TRUE,2,U64=TRUE,0),_xlfn.IFS(Q64=TRUE,6,R64=TRUE,4,AND(S64=TRUE,T64=FALSE),3,T64=TRUE,2,U64=TRUE,0))} -> 0
A65: ='Tabela de Jogos'!A65 -> 63 | B65: ='Tabela de Jogos'!B65 -> Cabo Verde | C65: ='Tabela de Jogos'!C65 -> 0 | D65: ='Tabela de Jogos'!D65 -> x | E65: ='Tabela de Jogos'!E65 -> 0 | F65: ='Tabela de Jogos'!F65 -> Arábia Saudita | G65: ='Tabela de Jogos'!G65 -> - | I65: =A65 -> 63 | J65: =B65 -> Cabo Verde | L65: =D65 -> x | N65: =F65 -> Arábia Saudita | O65: =IF(K65>M65,J65,IF(M65>K65,N65,IF(ISBLANK(K65),"-","Empate"))) -> - | Q65: =IF(AND(O65=G65,K65=C65,M65=E65,ISBLANK(K65)<>TRUE),TRUE,FALSE) -> FALSE | R65: =IF(OR(AND(O65=G65,K65=C65,K65>M65,M65<>E65,ISBLANK(K65)<>TRUE),AND(O65=G65,M65>K65,K65<>C65,M65=E65,ISBLANK(K65)<>TRUE)),TRUE,FALSE) -> FALSE | S65: =IF(AND(O65=G65,ABS(K65-M65)=ABS(C65-E65),OR(K65<>C65,M65<>E65),ISBLANK(K65)<>TRUE),TRUE,FALSE) -> FALSE | T65: =IF(OR(AND(O65=G65,Q65=FALSE,R65=FALSE,S65=FALSE,G65<>"-"),AND(O65="Empate",S65=TRUE)),TRUE,FALSE) -> FALSE | U65: =IF(AND(Q65=FALSE,R65=FALSE,S65=FALSE,T65=FALSE),TRUE,FALSE) -> TRUE | W65: {=IF(OR(J65="Brasil",N65="Brasil"),2*_xlfn.IFS(Q65=TRUE,6,R65=TRUE,4,AND(S65=TRUE,T65=FALSE),3,T65=TRUE,2,U65=TRUE,0),_xlfn.IFS(Q65=TRUE,6,R65=TRUE,4,AND(S65=TRUE,T65=FALSE),3,T65=TRUE,2,U65=TRUE,0))} -> 0
A66: ='Tabela de Jogos'!A66 -> 64 | B66: ='Tabela de Jogos'!B66 -> Uruguai | C66: ='Tabela de Jogos'!C66 -> 0 | D66: ='Tabela de Jogos'!D66 -> x | E66: ='Tabela de Jogos'!E66 -> 0 | F66: ='Tabela de Jogos'!F66 -> Espanha | G66: ='Tabela de Jogos'!G66 -> - | I66: =A66 -> 64 | J66: =B66 -> Uruguai | L66: =D66 -> x | N66: =F66 -> Espanha | O66: =IF(K66>M66,J66,IF(M66>K66,N66,IF(ISBLANK(K66),"-","Empate"))) -> - | Q66: =IF(AND(O66=G66,K66=C66,M66=E66,ISBLANK(K66)<>TRUE),TRUE,FALSE) -> FALSE | R66: =IF(OR(AND(O66=G66,K66=C66,K66>M66,M66<>E66,ISBLANK(K66)<>TRUE),AND(O66=G66,M66>K66,K66<>C66,M66=E66,ISBLANK(K66)<>TRUE)),TRUE,FALSE) -> FALSE | S66: =IF(AND(O66=G66,ABS(K66-M66)=ABS(C66-E66),OR(K66<>C66,M66<>E66),ISBLANK(K66)<>TRUE),TRUE,FALSE) -> FALSE | T66: =IF(OR(AND(O66=G66,Q66=FALSE,R66=FALSE,S66=FALSE,G66<>"-"),AND(O66="Empate",S66=TRUE)),TRUE,FALSE) -> FALSE | U66: =IF(AND(Q66=FALSE,R66=FALSE,S66=FALSE,T66=FALSE),TRUE,FALSE) -> TRUE | W66: {=IF(OR(J66="Brasil",N66="Brasil"),2*_xlfn.IFS(Q66=TRUE,6,R66=TRUE,4,AND(S66=TRUE,T66=FALSE),3,T66=TRUE,2,U66=TRUE,0),_xlfn.IFS(Q66=TRUE,6,R66=TRUE,4,AND(S66=TRUE,T66=FALSE),3,T66=TRUE,2,U66=TRUE,0))} -> 0
A67: ='Tabela de Jogos'!A67 -> 65 | B67: ='Tabela de Jogos'!B67 -> Nova Zelândia | C67: ='Tabela de Jogos'!C67 -> 0 | D67: ='Tabela de Jogos'!D67 -> x | E67: ='Tabela de Jogos'!E67 -> 0 | F67: ='Tabela de Jogos'!F67 -> Bélgica | G67: ='Tabela de Jogos'!G67 -> - | I67: =A67 -> 65 | J67: =B67 -> Nova Zelândia | L67: =D67 -> x | N67: =F67 -> Bélgica | O67: =IF(K67>M67,J67,IF(M67>K67,N67,IF(ISBLANK(K67),"-","Empate"))) -> - | Q67: =IF(AND(O67=G67,K67=C67,M67=E67,ISBLANK(K67)<>TRUE),TRUE,FALSE) -> FALSE | R67: =IF(OR(AND(O67=G67,K67=C67,K67>M67,M67<>E67,ISBLANK(K67)<>TRUE),AND(O67=G67,M67>K67,K67<>C67,M67=E67,ISBLANK(K67)<>TRUE)),TRUE,FALSE) -> FALSE | S67: =IF(AND(O67=G67,ABS(K67-M67)=ABS(C67-E67),OR(K67<>C67,M67<>E67),ISBLANK(K67)<>TRUE),TRUE,FALSE) -> FALSE | T67: =IF(OR(AND(O67=G67,Q67=FALSE,R67=FALSE,S67=FALSE,G67<>"-"),AND(O67="Empate",S67=TRUE)),TRUE,FALSE) -> FALSE | U67: =IF(AND(Q67=FALSE,R67=FALSE,S67=FALSE,T67=FALSE),TRUE,FALSE) -> TRUE | W67: {=IF(OR(J67="Brasil",N67="Brasil"),2*_xlfn.IFS(Q67=TRUE,6,R67=TRUE,4,AND(S67=TRUE,T67=FALSE),3,T67=TRUE,2,U67=TRUE,0),_xlfn.IFS(Q67=TRUE,6,R67=TRUE,4,AND(S67=TRUE,T67=FALSE),3,T67=TRUE,2,U67=TRUE,0))} -> 0
